2025-07-23 15:02:29,358 - __main__ - INFO - Starting periodic reply checking
2025-07-23 15:02:29,358 - __main__ - INFO - Reply checking thread started successfully
2025-07-23 15:19:15,792 - TeleBot - ERROR - Infinity polling exception: HTTPSConnectionPool(host='api.telegram.org', port=443): Read timed out. (read timeout=25)
2025-07-23 15:19:15,798 - TeleBot - ERROR - Exception traceback:
Traceback (most recent call last):
  File "c:\Users\User\AppData\Local\Programs\Python\Python312\Lib\site-packages\urllib3\connectionpool.py", line 534, in _make_request
    response = conn.getresponse()
               ^^^^^^^^^^^^^^^^^^
  File "c:\Users\User\AppData\Local\Programs\Python\Python312\Lib\site-packages\urllib3\connection.py", line 565, in getresponse
    httplib_response = super().getresponse()
                       ^^^^^^^^^^^^^^^^^^^^^
  File "c:\Users\User\AppData\Local\Programs\Python\Python312\Lib\http\client.py", line 1428, in getresponse
    response.begin()
  File "c:\Users\User\AppData\Local\Programs\Python\Python312\Lib\http\client.py", line 331, in begin
    version, status, reason = self._read_status()
                              ^^^^^^^^^^^^^^^^^^^
  File "c:\Users\User\AppData\Local\Programs\Python\Python312\Lib\http\client.py", line 292, in _read_status
    line = str(self.fp.readline(_MAXLINE + 1), "iso-8859-1")
               ^^^^^^^^^^^^^^^^^^^^^^^^^^^^^^
  File "c:\Users\User\AppData\Local\Programs\Python\Python312\Lib\socket.py", line 720, in readinto
    return self._sock.recv_into(b)
           ^^^^^^^^^^^^^^^^^^^^^^^
  File "c:\Users\User\AppData\Local\Programs\Python\Python312\Lib\ssl.py", line 1251, in recv_into
    return self.read(nbytes, buffer)
           ^^^^^^^^^^^^^^^^^^^^^^^^^
  File "c:\Users\User\AppData\Local\Programs\Python\Python312\Lib\ssl.py", line 1103, in read
    return self._sslobj.read(len, buffer)
           ^^^^^^^^^^^^^^^^^^^^^^^^^^^^^^
TimeoutError: The read operation timed out

The above exception was the direct cause of the following exception:

Traceback (most recent call last):
  File "c:\Users\User\AppData\Local\Programs\Python\Python312\Lib\site-packages\requests\adapters.py", line 667, in send
    resp = conn.urlopen(
           ^^^^^^^^^^^^^
  File "c:\Users\User\AppData\Local\Programs\Python\Python312\Lib\site-packages\urllib3\connectionpool.py", line 841, in urlopen
    retries = retries.increment(
              ^^^^^^^^^^^^^^^^^^
  File "c:\Users\User\AppData\Local\Programs\Python\Python312\Lib\site-packages\urllib3\util\retry.py", line 474, in increment
    raise reraise(type(error), error, _stacktrace)
          ^^^^^^^^^^^^^^^^^^^^^^^^^^^^^^^^^^^^^^^^
  File "c:\Users\User\AppData\Local\Programs\Python\Python312\Lib\site-packages\urllib3\util\util.py", line 39, in reraise
    raise value
  File "c:\Users\User\AppData\Local\Programs\Python\Python312\Lib\site-packages\urllib3\connectionpool.py", line 787, in urlopen
    response = self._make_request(
               ^^^^^^^^^^^^^^^^^^^
  File "c:\Users\User\AppData\Local\Programs\Python\Python312\Lib\site-packages\urllib3\connectionpool.py", line 536, in _make_request
    self._raise_timeout(err=e, url=url, timeout_value=read_timeout)
  File "c:\Users\User\AppData\Local\Programs\Python\Python312\Lib\site-packages\urllib3\connectionpool.py", line 367, in _raise_timeout
    raise ReadTimeoutError(
urllib3.exceptions.ReadTimeoutError: HTTPSConnectionPool(host='api.telegram.org', port=443): Read timed out. (read timeout=25)

During handling of the above exception, another exception occurred:

Traceback (most recent call last):
  File "c:\Users\User\AppData\Local\Programs\Python\Python312\Lib\site-packages\telebot\__init__.py", line 1110, in infinity_polling
    self.polling(non_stop=True, timeout=timeout, long_polling_timeout=long_polling_timeout,
  File "c:\Users\User\AppData\Local\Programs\Python\Python312\Lib\site-packages\telebot\__init__.py", line 1198, in polling
    self.__threaded_polling(non_stop=non_stop, interval=interval, timeout=timeout, long_polling_timeout=long_polling_timeout,
  File "c:\Users\User\AppData\Local\Programs\Python\Python312\Lib\site-packages\telebot\__init__.py", line 1273, in __threaded_polling
    raise e
  File "c:\Users\User\AppData\Local\Programs\Python\Python312\Lib\site-packages\telebot\__init__.py", line 1234, in __threaded_polling
    polling_thread.raise_exceptions()
  File "c:\Users\User\AppData\Local\Programs\Python\Python312\Lib\site-packages\telebot\util.py", line 111, in raise_exceptions
    raise self.exception_info
  File "c:\Users\User\AppData\Local\Programs\Python\Python312\Lib\site-packages\telebot\util.py", line 93, in run
    task(*args, **kwargs)
  File "c:\Users\User\AppData\Local\Programs\Python\Python312\Lib\site-packages\telebot\__init__.py", line 688, in __retrieve_updates
    updates = self.get_updates(offset=(self.last_update_id + 1),
             ^^^^^^^^^^^^^^^^^^^^^^^^^^^^^^^^^^^^^^^^^^^^^^^^^^
  File "c:\Users\User\AppData\Local\Programs\Python\Python312\Lib\site-packages\telebot\__init__.py", line 660, in get_updates
    json_updates = apihelper.get_updates(
                   ^^^^^^^^^^^^^^^^^^^^^^
  File "c:\Users\User\AppData\Local\Programs\Python\Python312\Lib\site-packages\telebot\apihelper.py", line 332, in get_updates
    return _make_request(token, method_url, params=payload)
           ^^^^^^^^^^^^^^^^^^^^^^^^^^^^^^^^^^^^^^^^^^^^^^^^
  File "c:\Users\User\AppData\Local\Programs\Python\Python312\Lib\site-packages\telebot\apihelper.py", line 162, in _make_request
    result = _get_req_session().request(
             ^^^^^^^^^^^^^^^^^^^^^^^^^^^
  File "c:\Users\User\AppData\Local\Programs\Python\Python312\Lib\site-packages\requests\sessions.py", line 589, in request
    resp = self.send(prep, **send_kwargs)
           ^^^^^^^^^^^^^^^^^^^^^^^^^^^^^^
  File "c:\Users\User\AppData\Local\Programs\Python\Python312\Lib\site-packages\requests\sessions.py", line 703, in send
    r = adapter.send(request, **kwargs)
        ^^^^^^^^^^^^^^^^^^^^^^^^^^^^^^^
  File "c:\Users\User\AppData\Local\Programs\Python\Python312\Lib\site-packages\requests\adapters.py", line 713, in send
    raise ReadTimeout(e, request=request)
requests.exceptions.ReadTimeout: HTTPSConnectionPool(host='api.telegram.org', port=443): Read timed out. (read timeout=25)

2025-07-23 15:38:34,742 - TeleBot - ERROR - Infinity polling exception: HTTPSConnectionPool(host='api.telegram.org', port=443): Read timed out. (read timeout=25)
2025-07-23 15:38:34,745 - TeleBot - ERROR - Exception traceback:
Traceback (most recent call last):
  File "c:\Users\User\AppData\Local\Programs\Python\Python312\Lib\site-packages\urllib3\connectionpool.py", line 534, in _make_request
    response = conn.getresponse()
               ^^^^^^^^^^^^^^^^^^
  File "c:\Users\User\AppData\Local\Programs\Python\Python312\Lib\site-packages\urllib3\connection.py", line 565, in getresponse
    httplib_response = super().getresponse()
                       ^^^^^^^^^^^^^^^^^^^^^
  File "c:\Users\User\AppData\Local\Programs\Python\Python312\Lib\http\client.py", line 1428, in getresponse
    response.begin()
  File "c:\Users\User\AppData\Local\Programs\Python\Python312\Lib\http\client.py", line 331, in begin
    version, status, reason = self._read_status()
                              ^^^^^^^^^^^^^^^^^^^
  File "c:\Users\User\AppData\Local\Programs\Python\Python312\Lib\http\client.py", line 292, in _read_status
    line = str(self.fp.readline(_MAXLINE + 1), "iso-8859-1")
               ^^^^^^^^^^^^^^^^^^^^^^^^^^^^^^
  File "c:\Users\User\AppData\Local\Programs\Python\Python312\Lib\socket.py", line 720, in readinto
    return self._sock.recv_into(b)
           ^^^^^^^^^^^^^^^^^^^^^^^
  File "c:\Users\User\AppData\Local\Programs\Python\Python312\Lib\ssl.py", line 1251, in recv_into
    return self.read(nbytes, buffer)
           ^^^^^^^^^^^^^^^^^^^^^^^^^
  File "c:\Users\User\AppData\Local\Programs\Python\Python312\Lib\ssl.py", line 1103, in read
    return self._sslobj.read(len, buffer)
           ^^^^^^^^^^^^^^^^^^^^^^^^^^^^^^
TimeoutError: The read operation timed out

The above exception was the direct cause of the following exception:

Traceback (most recent call last):
  File "c:\Users\User\AppData\Local\Programs\Python\Python312\Lib\site-packages\requests\adapters.py", line 667, in send
    resp = conn.urlopen(
           ^^^^^^^^^^^^^
  File "c:\Users\User\AppData\Local\Programs\Python\Python312\Lib\site-packages\urllib3\connectionpool.py", line 841, in urlopen
    retries = retries.increment(
              ^^^^^^^^^^^^^^^^^^
  File "c:\Users\User\AppData\Local\Programs\Python\Python312\Lib\site-packages\urllib3\util\retry.py", line 474, in increment
    raise reraise(type(error), error, _stacktrace)
          ^^^^^^^^^^^^^^^^^^^^^^^^^^^^^^^^^^^^^^^^
  File "c:\Users\User\AppData\Local\Programs\Python\Python312\Lib\site-packages\urllib3\util\util.py", line 39, in reraise
    raise value
  File "c:\Users\User\AppData\Local\Programs\Python\Python312\Lib\site-packages\urllib3\connectionpool.py", line 787, in urlopen
    response = self._make_request(
               ^^^^^^^^^^^^^^^^^^^
  File "c:\Users\User\AppData\Local\Programs\Python\Python312\Lib\site-packages\urllib3\connectionpool.py", line 536, in _make_request
    self._raise_timeout(err=e, url=url, timeout_value=read_timeout)
  File "c:\Users\User\AppData\Local\Programs\Python\Python312\Lib\site-packages\urllib3\connectionpool.py", line 367, in _raise_timeout
    raise ReadTimeoutError(
urllib3.exceptions.ReadTimeoutError: HTTPSConnectionPool(host='api.telegram.org', port=443): Read timed out. (read timeout=25)

During handling of the above exception, another exception occurred:

Traceback (most recent call last):
  File "c:\Users\User\AppData\Local\Programs\Python\Python312\Lib\site-packages\telebot\__init__.py", line 1110, in infinity_polling
    self.polling(non_stop=True, timeout=timeout, long_polling_timeout=long_polling_timeout,
  File "c:\Users\User\AppData\Local\Programs\Python\Python312\Lib\site-packages\telebot\__init__.py", line 1198, in polling
    self.__threaded_polling(non_stop=non_stop, interval=interval, timeout=timeout, long_polling_timeout=long_polling_timeout,
  File "c:\Users\User\AppData\Local\Programs\Python\Python312\Lib\site-packages\telebot\__init__.py", line 1273, in __threaded_polling
    raise e
  File "c:\Users\User\AppData\Local\Programs\Python\Python312\Lib\site-packages\telebot\__init__.py", line 1234, in __threaded_polling
    polling_thread.raise_exceptions()
  File "c:\Users\User\AppData\Local\Programs\Python\Python312\Lib\site-packages\telebot\util.py", line 111, in raise_exceptions
    raise self.exception_info
  File "c:\Users\User\AppData\Local\Programs\Python\Python312\Lib\site-packages\telebot\util.py", line 93, in run
    task(*args, **kwargs)
  File "c:\Users\User\AppData\Local\Programs\Python\Python312\Lib\site-packages\telebot\__init__.py", line 688, in __retrieve_updates
    updates = self.get_updates(offset=(self.last_update_id + 1),
             ^^^^^^^^^^^^^^^^^^^^^^^^^^^^^^^^^^^^^^^^^^^^^^^^^^
  File "c:\Users\User\AppData\Local\Programs\Python\Python312\Lib\site-packages\telebot\__init__.py", line 660, in get_updates
    json_updates = apihelper.get_updates(
                   ^^^^^^^^^^^^^^^^^^^^^^
  File "c:\Users\User\AppData\Local\Programs\Python\Python312\Lib\site-packages\telebot\apihelper.py", line 332, in get_updates
    return _make_request(token, method_url, params=payload)
           ^^^^^^^^^^^^^^^^^^^^^^^^^^^^^^^^^^^^^^^^^^^^^^^^
  File "c:\Users\User\AppData\Local\Programs\Python\Python312\Lib\site-packages\telebot\apihelper.py", line 162, in _make_request
    result = _get_req_session().request(
             ^^^^^^^^^^^^^^^^^^^^^^^^^^^
  File "c:\Users\User\AppData\Local\Programs\Python\Python312\Lib\site-packages\requests\sessions.py", line 589, in request
    resp = self.send(prep, **send_kwargs)
           ^^^^^^^^^^^^^^^^^^^^^^^^^^^^^^
  File "c:\Users\User\AppData\Local\Programs\Python\Python312\Lib\site-packages\requests\sessions.py", line 703, in send
    r = adapter.send(request, **kwargs)
        ^^^^^^^^^^^^^^^^^^^^^^^^^^^^^^^
  File "c:\Users\User\AppData\Local\Programs\Python\Python312\Lib\site-packages\requests\adapters.py", line 713, in send
    raise ReadTimeout(e, request=request)
requests.exceptions.ReadTimeout: HTTPSConnectionPool(host='api.telegram.org', port=443): Read timed out. (read timeout=25)

2025-07-23 15:40:46,213 - TeleBot - ERROR - Infinity polling exception: HTTPSConnectionPool(host='api.telegram.org', port=443): Read timed out. (read timeout=25)
2025-07-23 15:40:46,215 - TeleBot - ERROR - Exception traceback:
Traceback (most recent call last):
  File "c:\Users\User\AppData\Local\Programs\Python\Python312\Lib\site-packages\urllib3\connectionpool.py", line 534, in _make_request
    response = conn.getresponse()
               ^^^^^^^^^^^^^^^^^^
  File "c:\Users\User\AppData\Local\Programs\Python\Python312\Lib\site-packages\urllib3\connection.py", line 565, in getresponse
    httplib_response = super().getresponse()
                       ^^^^^^^^^^^^^^^^^^^^^
  File "c:\Users\User\AppData\Local\Programs\Python\Python312\Lib\http\client.py", line 1428, in getresponse
    response.begin()
  File "c:\Users\User\AppData\Local\Programs\Python\Python312\Lib\http\client.py", line 331, in begin
    version, status, reason = self._read_status()
                              ^^^^^^^^^^^^^^^^^^^
  File "c:\Users\User\AppData\Local\Programs\Python\Python312\Lib\http\client.py", line 292, in _read_status
    line = str(self.fp.readline(_MAXLINE + 1), "iso-8859-1")
               ^^^^^^^^^^^^^^^^^^^^^^^^^^^^^^
  File "c:\Users\User\AppData\Local\Programs\Python\Python312\Lib\socket.py", line 720, in readinto
    return self._sock.recv_into(b)
           ^^^^^^^^^^^^^^^^^^^^^^^
  File "c:\Users\User\AppData\Local\Programs\Python\Python312\Lib\ssl.py", line 1251, in recv_into
    return self.read(nbytes, buffer)
           ^^^^^^^^^^^^^^^^^^^^^^^^^
  File "c:\Users\User\AppData\Local\Programs\Python\Python312\Lib\ssl.py", line 1103, in read
    return self._sslobj.read(len, buffer)
           ^^^^^^^^^^^^^^^^^^^^^^^^^^^^^^
TimeoutError: The read operation timed out

The above exception was the direct cause of the following exception:

Traceback (most recent call last):
  File "c:\Users\User\AppData\Local\Programs\Python\Python312\Lib\site-packages\requests\adapters.py", line 667, in send
    resp = conn.urlopen(
           ^^^^^^^^^^^^^
  File "c:\Users\User\AppData\Local\Programs\Python\Python312\Lib\site-packages\urllib3\connectionpool.py", line 841, in urlopen
    retries = retries.increment(
              ^^^^^^^^^^^^^^^^^^
  File "c:\Users\User\AppData\Local\Programs\Python\Python312\Lib\site-packages\urllib3\util\retry.py", line 474, in increment
    raise reraise(type(error), error, _stacktrace)
          ^^^^^^^^^^^^^^^^^^^^^^^^^^^^^^^^^^^^^^^^
  File "c:\Users\User\AppData\Local\Programs\Python\Python312\Lib\site-packages\urllib3\util\util.py", line 39, in reraise
    raise value
  File "c:\Users\User\AppData\Local\Programs\Python\Python312\Lib\site-packages\urllib3\connectionpool.py", line 787, in urlopen
    response = self._make_request(
               ^^^^^^^^^^^^^^^^^^^
  File "c:\Users\User\AppData\Local\Programs\Python\Python312\Lib\site-packages\urllib3\connectionpool.py", line 536, in _make_request
    self._raise_timeout(err=e, url=url, timeout_value=read_timeout)
  File "c:\Users\User\AppData\Local\Programs\Python\Python312\Lib\site-packages\urllib3\connectionpool.py", line 367, in _raise_timeout
    raise ReadTimeoutError(
urllib3.exceptions.ReadTimeoutError: HTTPSConnectionPool(host='api.telegram.org', port=443): Read timed out. (read timeout=25)

During handling of the above exception, another exception occurred:

Traceback (most recent call last):
  File "c:\Users\User\AppData\Local\Programs\Python\Python312\Lib\site-packages\telebot\__init__.py", line 1110, in infinity_polling
    self.polling(non_stop=True, timeout=timeout, long_polling_timeout=long_polling_timeout,
  File "c:\Users\User\AppData\Local\Programs\Python\Python312\Lib\site-packages\telebot\__init__.py", line 1198, in polling
    self.__threaded_polling(non_stop=non_stop, interval=interval, timeout=timeout, long_polling_timeout=long_polling_timeout,
  File "c:\Users\User\AppData\Local\Programs\Python\Python312\Lib\site-packages\telebot\__init__.py", line 1273, in __threaded_polling
    raise e
  File "c:\Users\User\AppData\Local\Programs\Python\Python312\Lib\site-packages\telebot\__init__.py", line 1234, in __threaded_polling
    polling_thread.raise_exceptions()
  File "c:\Users\User\AppData\Local\Programs\Python\Python312\Lib\site-packages\telebot\util.py", line 111, in raise_exceptions
    raise self.exception_info
  File "c:\Users\User\AppData\Local\Programs\Python\Python312\Lib\site-packages\telebot\util.py", line 93, in run
    task(*args, **kwargs)
  File "c:\Users\User\AppData\Local\Programs\Python\Python312\Lib\site-packages\telebot\__init__.py", line 688, in __retrieve_updates
    updates = self.get_updates(offset=(self.last_update_id + 1),
             ^^^^^^^^^^^^^^^^^^^^^^^^^^^^^^^^^^^^^^^^^^^^^^^^^^
  File "c:\Users\User\AppData\Local\Programs\Python\Python312\Lib\site-packages\telebot\__init__.py", line 660, in get_updates
    json_updates = apihelper.get_updates(
                   ^^^^^^^^^^^^^^^^^^^^^^
  File "c:\Users\User\AppData\Local\Programs\Python\Python312\Lib\site-packages\telebot\apihelper.py", line 332, in get_updates
    return _make_request(token, method_url, params=payload)
           ^^^^^^^^^^^^^^^^^^^^^^^^^^^^^^^^^^^^^^^^^^^^^^^^
  File "c:\Users\User\AppData\Local\Programs\Python\Python312\Lib\site-packages\telebot\apihelper.py", line 162, in _make_request
    result = _get_req_session().request(
             ^^^^^^^^^^^^^^^^^^^^^^^^^^^
  File "c:\Users\User\AppData\Local\Programs\Python\Python312\Lib\site-packages\requests\sessions.py", line 589, in request
    resp = self.send(prep, **send_kwargs)
           ^^^^^^^^^^^^^^^^^^^^^^^^^^^^^^
  File "c:\Users\User\AppData\Local\Programs\Python\Python312\Lib\site-packages\requests\sessions.py", line 703, in send
    r = adapter.send(request, **kwargs)
        ^^^^^^^^^^^^^^^^^^^^^^^^^^^^^^^
  File "c:\Users\User\AppData\Local\Programs\Python\Python312\Lib\site-packages\requests\adapters.py", line 713, in send
    raise ReadTimeout(e, request=request)
requests.exceptions.ReadTimeout: HTTPSConnectionPool(host='api.telegram.org', port=443): Read timed out. (read timeout=25)

2025-07-23 20:58:09,965 - TeleBot - ERROR - Infinity polling exception: ('Connection aborted.', RemoteDisconnected('Remote end closed connection without response'))
2025-07-23 20:58:10,436 - TeleBot - ERROR - Exception traceback:
Traceback (most recent call last):
  File "c:\Users\User\AppData\Local\Programs\Python\Python312\Lib\site-packages\urllib3\connectionpool.py", line 787, in urlopen
    response = self._make_request(
               ^^^^^^^^^^^^^^^^^^^
  File "c:\Users\User\AppData\Local\Programs\Python\Python312\Lib\site-packages\urllib3\connectionpool.py", line 534, in _make_request
    response = conn.getresponse()
               ^^^^^^^^^^^^^^^^^^
  File "c:\Users\User\AppData\Local\Programs\Python\Python312\Lib\site-packages\urllib3\connection.py", line 565, in getresponse
    httplib_response = super().getresponse()
                       ^^^^^^^^^^^^^^^^^^^^^
  File "c:\Users\User\AppData\Local\Programs\Python\Python312\Lib\http\client.py", line 1428, in getresponse
    response.begin()
  File "c:\Users\User\AppData\Local\Programs\Python\Python312\Lib\http\client.py", line 331, in begin
    version, status, reason = self._read_status()
                              ^^^^^^^^^^^^^^^^^^^
  File "c:\Users\User\AppData\Local\Programs\Python\Python312\Lib\http\client.py", line 300, in _read_status
    raise RemoteDisconnected("Remote end closed connection without"
http.client.RemoteDisconnected: Remote end closed connection without response

During handling of the above exception, another exception occurred:

Traceback (most recent call last):
  File "c:\Users\User\AppData\Local\Programs\Python\Python312\Lib\site-packages\requests\adapters.py", line 667, in send
    resp = conn.urlopen(
           ^^^^^^^^^^^^^
  File "c:\Users\User\AppData\Local\Programs\Python\Python312\Lib\site-packages\urllib3\connectionpool.py", line 841, in urlopen
    retries = retries.increment(
              ^^^^^^^^^^^^^^^^^^
  File "c:\Users\User\AppData\Local\Programs\Python\Python312\Lib\site-packages\urllib3\util\retry.py", line 474, in increment
    raise reraise(type(error), error, _stacktrace)
          ^^^^^^^^^^^^^^^^^^^^^^^^^^^^^^^^^^^^^^^^
  File "c:\Users\User\AppData\Local\Programs\Python\Python312\Lib\site-packages\urllib3\util\util.py", line 38, in reraise
    raise value.with_traceback(tb)
  File "c:\Users\User\AppData\Local\Programs\Python\Python312\Lib\site-packages\urllib3\connectionpool.py", line 787, in urlopen
    response = self._make_request(
               ^^^^^^^^^^^^^^^^^^^
  File "c:\Users\User\AppData\Local\Programs\Python\Python312\Lib\site-packages\urllib3\connectionpool.py", line 534, in _make_request
    response = conn.getresponse()
               ^^^^^^^^^^^^^^^^^^
  File "c:\Users\User\AppData\Local\Programs\Python\Python312\Lib\site-packages\urllib3\connection.py", line 565, in getresponse
    httplib_response = super().getresponse()
                       ^^^^^^^^^^^^^^^^^^^^^
  File "c:\Users\User\AppData\Local\Programs\Python\Python312\Lib\http\client.py", line 1428, in getresponse
    response.begin()
  File "c:\Users\User\AppData\Local\Programs\Python\Python312\Lib\http\client.py", line 331, in begin
    version, status, reason = self._read_status()
                              ^^^^^^^^^^^^^^^^^^^
  File "c:\Users\User\AppData\Local\Programs\Python\Python312\Lib\http\client.py", line 300, in _read_status
    raise RemoteDisconnected("Remote end closed connection without"
urllib3.exceptions.ProtocolError: ('Connection aborted.', RemoteDisconnected('Remote end closed connection without response'))

During handling of the above exception, another exception occurred:

Traceback (most recent call last):
  File "c:\Users\User\AppData\Local\Programs\Python\Python312\Lib\site-packages\telebot\__init__.py", line 1110, in infinity_polling
    self.polling(non_stop=True, timeout=timeout, long_polling_timeout=long_polling_timeout,
  File "c:\Users\User\AppData\Local\Programs\Python\Python312\Lib\site-packages\telebot\__init__.py", line 1198, in polling
    self.__threaded_polling(non_stop=non_stop, interval=interval, timeout=timeout, long_polling_timeout=long_polling_timeout,
  File "c:\Users\User\AppData\Local\Programs\Python\Python312\Lib\site-packages\telebot\__init__.py", line 1273, in __threaded_polling
    raise e
  File "c:\Users\User\AppData\Local\Programs\Python\Python312\Lib\site-packages\telebot\__init__.py", line 1234, in __threaded_polling
    polling_thread.raise_exceptions()
  File "c:\Users\User\AppData\Local\Programs\Python\Python312\Lib\site-packages\telebot\util.py", line 111, in raise_exceptions
    raise self.exception_info
  File "c:\Users\User\AppData\Local\Programs\Python\Python312\Lib\site-packages\telebot\util.py", line 93, in run
    task(*args, **kwargs)
  File "c:\Users\User\AppData\Local\Programs\Python\Python312\Lib\site-packages\telebot\__init__.py", line 688, in __retrieve_updates
    updates = self.get_updates(offset=(self.last_update_id + 1),
             ^^^^^^^^^^^^^^^^^^^^^^^^^^^^^^^^^^^^^^^^^^^^^^^^^^
  File "c:\Users\User\AppData\Local\Programs\Python\Python312\Lib\site-packages\telebot\__init__.py", line 660, in get_updates
    json_updates = apihelper.get_updates(
                   ^^^^^^^^^^^^^^^^^^^^^^
  File "c:\Users\User\AppData\Local\Programs\Python\Python312\Lib\site-packages\telebot\apihelper.py", line 332, in get_updates
    return _make_request(token, method_url, params=payload)
           ^^^^^^^^^^^^^^^^^^^^^^^^^^^^^^^^^^^^^^^^^^^^^^^^
  File "c:\Users\User\AppData\Local\Programs\Python\Python312\Lib\site-packages\telebot\apihelper.py", line 162, in _make_request
    result = _get_req_session().request(
             ^^^^^^^^^^^^^^^^^^^^^^^^^^^
  File "c:\Users\User\AppData\Local\Programs\Python\Python312\Lib\site-packages\requests\sessions.py", line 589, in request
    resp = self.send(prep, **send_kwargs)
           ^^^^^^^^^^^^^^^^^^^^^^^^^^^^^^
  File "c:\Users\User\AppData\Local\Programs\Python\Python312\Lib\site-packages\requests\sessions.py", line 703, in send
    r = adapter.send(request, **kwargs)
        ^^^^^^^^^^^^^^^^^^^^^^^^^^^^^^^
  File "c:\Users\User\AppData\Local\Programs\Python\Python312\Lib\site-packages\requests\adapters.py", line 682, in send
    raise ConnectionError(err, request=request)
requests.exceptions.ConnectionError: ('Connection aborted.', RemoteDisconnected('Remote end closed connection without response'))

2025-07-23 20:58:13,708 - TeleBot - ERROR - Infinity polling exception: HTTPSConnectionPool(host='api.telegram.org', port=443): Max retries exceeded with url: /bot8120214959:***********************************/getUpdates?offset=1&timeout=20 (Caused by NameResolutionError("<urllib3.connection.HTTPSConnection object at 0x000001851C4686E0>: Failed to resolve 'api.telegram.org' ([Errno 11001] getaddrinfo failed)"))
2025-07-23 20:58:13,719 - TeleBot - ERROR - Exception traceback:
Traceback (most recent call last):
  File "c:\Users\User\AppData\Local\Programs\Python\Python312\Lib\site-packages\urllib3\connection.py", line 198, in _new_conn
    sock = connection.create_connection(
           ^^^^^^^^^^^^^^^^^^^^^^^^^^^^^
  File "c:\Users\User\AppData\Local\Programs\Python\Python312\Lib\site-packages\urllib3\util\connection.py", line 60, in create_connection
    for res in socket.getaddrinfo(host, port, family, socket.SOCK_STREAM):
               ^^^^^^^^^^^^^^^^^^^^^^^^^^^^^^^^^^^^^^^^^^^^^^^^^^^^^^^^^^
  File "c:\Users\User\AppData\Local\Programs\Python\Python312\Lib\socket.py", line 976, in getaddrinfo
    for res in _socket.getaddrinfo(host, port, family, type, proto, flags):
               ^^^^^^^^^^^^^^^^^^^^^^^^^^^^^^^^^^^^^^^^^^^^^^^^^^^^^^^^^^^
socket.gaierror: [Errno 11001] getaddrinfo failed

The above exception was the direct cause of the following exception:

Traceback (most recent call last):
  File "c:\Users\User\AppData\Local\Programs\Python\Python312\Lib\site-packages\urllib3\connectionpool.py", line 787, in urlopen
    response = self._make_request(
               ^^^^^^^^^^^^^^^^^^^
  File "c:\Users\User\AppData\Local\Programs\Python\Python312\Lib\site-packages\urllib3\connectionpool.py", line 488, in _make_request
    raise new_e
  File "c:\Users\User\AppData\Local\Programs\Python\Python312\Lib\site-packages\urllib3\connectionpool.py", line 464, in _make_request
    self._validate_conn(conn)
  File "c:\Users\User\AppData\Local\Programs\Python\Python312\Lib\site-packages\urllib3\connectionpool.py", line 1093, in _validate_conn
    conn.connect()
  File "c:\Users\User\AppData\Local\Programs\Python\Python312\Lib\site-packages\urllib3\connection.py", line 753, in connect
    self.sock = sock = self._new_conn()
                       ^^^^^^^^^^^^^^^^
  File "c:\Users\User\AppData\Local\Programs\Python\Python312\Lib\site-packages\urllib3\connection.py", line 205, in _new_conn
    raise NameResolutionError(self.host, self, e) from e
urllib3.exceptions.NameResolutionError: <urllib3.connection.HTTPSConnection object at 0x000001851C4686E0>: Failed to resolve 'api.telegram.org' ([Errno 11001] getaddrinfo failed)

The above exception was the direct cause of the following exception:

Traceback (most recent call last):
  File "c:\Users\User\AppData\Local\Programs\Python\Python312\Lib\site-packages\requests\adapters.py", line 667, in send
    resp = conn.urlopen(
           ^^^^^^^^^^^^^
  File "c:\Users\User\AppData\Local\Programs\Python\Python312\Lib\site-packages\urllib3\connectionpool.py", line 841, in urlopen
    retries = retries.increment(
              ^^^^^^^^^^^^^^^^^^
  File "c:\Users\User\AppData\Local\Programs\Python\Python312\Lib\site-packages\urllib3\util\retry.py", line 519, in increment
    raise MaxRetryError(_pool, url, reason) from reason  # type: ignore[arg-type]
    ^^^^^^^^^^^^^^^^^^^^^^^^^^^^^^^^^^^^^^^^^^^^^^^^^^^
urllib3.exceptions.MaxRetryError: HTTPSConnectionPool(host='api.telegram.org', port=443): Max retries exceeded with url: /bot8120214959:***********************************/getUpdates?offset=1&timeout=20 (Caused by NameResolutionError("<urllib3.connection.HTTPSConnection object at 0x000001851C4686E0>: Failed to resolve 'api.telegram.org' ([Errno 11001] getaddrinfo failed)"))

During handling of the above exception, another exception occurred:

Traceback (most recent call last):
  File "c:\Users\User\AppData\Local\Programs\Python\Python312\Lib\site-packages\telebot\__init__.py", line 1110, in infinity_polling
    self.polling(non_stop=True, timeout=timeout, long_polling_timeout=long_polling_timeout,
  File "c:\Users\User\AppData\Local\Programs\Python\Python312\Lib\site-packages\telebot\__init__.py", line 1198, in polling
    self.__threaded_polling(non_stop=non_stop, interval=interval, timeout=timeout, long_polling_timeout=long_polling_timeout,
  File "c:\Users\User\AppData\Local\Programs\Python\Python312\Lib\site-packages\telebot\__init__.py", line 1273, in __threaded_polling
    raise e
  File "c:\Users\User\AppData\Local\Programs\Python\Python312\Lib\site-packages\telebot\__init__.py", line 1234, in __threaded_polling
    polling_thread.raise_exceptions()
  File "c:\Users\User\AppData\Local\Programs\Python\Python312\Lib\site-packages\telebot\util.py", line 111, in raise_exceptions
    raise self.exception_info
  File "c:\Users\User\AppData\Local\Programs\Python\Python312\Lib\site-packages\telebot\util.py", line 93, in run
    task(*args, **kwargs)
  File "c:\Users\User\AppData\Local\Programs\Python\Python312\Lib\site-packages\telebot\__init__.py", line 688, in __retrieve_updates
    updates = self.get_updates(offset=(self.last_update_id + 1),
             ^^^^^^^^^^^^^^^^^^^^^^^^^^^^^^^^^^^^^^^^^^^^^^^^^^
  File "c:\Users\User\AppData\Local\Programs\Python\Python312\Lib\site-packages\telebot\__init__.py", line 660, in get_updates
    json_updates = apihelper.get_updates(
                   ^^^^^^^^^^^^^^^^^^^^^^
  File "c:\Users\User\AppData\Local\Programs\Python\Python312\Lib\site-packages\telebot\apihelper.py", line 332, in get_updates
    return _make_request(token, method_url, params=payload)
           ^^^^^^^^^^^^^^^^^^^^^^^^^^^^^^^^^^^^^^^^^^^^^^^^
  File "c:\Users\User\AppData\Local\Programs\Python\Python312\Lib\site-packages\telebot\apihelper.py", line 162, in _make_request
    result = _get_req_session().request(
             ^^^^^^^^^^^^^^^^^^^^^^^^^^^
  File "c:\Users\User\AppData\Local\Programs\Python\Python312\Lib\site-packages\requests\sessions.py", line 589, in request
    resp = self.send(prep, **send_kwargs)
           ^^^^^^^^^^^^^^^^^^^^^^^^^^^^^^
  File "c:\Users\User\AppData\Local\Programs\Python\Python312\Lib\site-packages\requests\sessions.py", line 703, in send
    r = adapter.send(request, **kwargs)
        ^^^^^^^^^^^^^^^^^^^^^^^^^^^^^^^
  File "c:\Users\User\AppData\Local\Programs\Python\Python312\Lib\site-packages\requests\adapters.py", line 700, in send
    raise ConnectionError(e, request=request)
requests.exceptions.ConnectionError: HTTPSConnectionPool(host='api.telegram.org', port=443): Max retries exceeded with url: /bot8120214959:***********************************/getUpdates?offset=1&timeout=20 (Caused by NameResolutionError("<urllib3.connection.HTTPSConnection object at 0x000001851C4686E0>: Failed to resolve 'api.telegram.org' ([Errno 11001] getaddrinfo failed)"))

2025-07-23 21:03:17,494 - TeleBot - ERROR - Infinity polling exception: HTTPSConnectionPool(host='api.telegram.org', port=443): Max retries exceeded with url: /bot8120214959:***********************************/getUpdates?offset=1&timeout=20 (Caused by NameResolutionError("<urllib3.connection.HTTPSConnection object at 0x000001851BF9DF70>: Failed to resolve 'api.telegram.org' ([Errno 11001] getaddrinfo failed)"))
2025-07-23 21:03:17,544 - TeleBot - ERROR - Exception traceback:
Traceback (most recent call last):
  File "c:\Users\User\AppData\Local\Programs\Python\Python312\Lib\site-packages\urllib3\connection.py", line 198, in _new_conn
    sock = connection.create_connection(
           ^^^^^^^^^^^^^^^^^^^^^^^^^^^^^
  File "c:\Users\User\AppData\Local\Programs\Python\Python312\Lib\site-packages\urllib3\util\connection.py", line 60, in create_connection
    for res in socket.getaddrinfo(host, port, family, socket.SOCK_STREAM):
               ^^^^^^^^^^^^^^^^^^^^^^^^^^^^^^^^^^^^^^^^^^^^^^^^^^^^^^^^^^
  File "c:\Users\User\AppData\Local\Programs\Python\Python312\Lib\socket.py", line 976, in getaddrinfo
    for res in _socket.getaddrinfo(host, port, family, type, proto, flags):
               ^^^^^^^^^^^^^^^^^^^^^^^^^^^^^^^^^^^^^^^^^^^^^^^^^^^^^^^^^^^
socket.gaierror: [Errno 11001] getaddrinfo failed

The above exception was the direct cause of the following exception:

Traceback (most recent call last):
  File "c:\Users\User\AppData\Local\Programs\Python\Python312\Lib\site-packages\urllib3\connectionpool.py", line 787, in urlopen
    response = self._make_request(
               ^^^^^^^^^^^^^^^^^^^
  File "c:\Users\User\AppData\Local\Programs\Python\Python312\Lib\site-packages\urllib3\connectionpool.py", line 488, in _make_request
    raise new_e
  File "c:\Users\User\AppData\Local\Programs\Python\Python312\Lib\site-packages\urllib3\connectionpool.py", line 464, in _make_request
    self._validate_conn(conn)
  File "c:\Users\User\AppData\Local\Programs\Python\Python312\Lib\site-packages\urllib3\connectionpool.py", line 1093, in _validate_conn
    conn.connect()
  File "c:\Users\User\AppData\Local\Programs\Python\Python312\Lib\site-packages\urllib3\connection.py", line 753, in connect
    self.sock = sock = self._new_conn()
                       ^^^^^^^^^^^^^^^^
  File "c:\Users\User\AppData\Local\Programs\Python\Python312\Lib\site-packages\urllib3\connection.py", line 205, in _new_conn
    raise NameResolutionError(self.host, self, e) from e
urllib3.exceptions.NameResolutionError: <urllib3.connection.HTTPSConnection object at 0x000001851BF9DF70>: Failed to resolve 'api.telegram.org' ([Errno 11001] getaddrinfo failed)

The above exception was the direct cause of the following exception:

Traceback (most recent call last):
  File "c:\Users\User\AppData\Local\Programs\Python\Python312\Lib\site-packages\requests\adapters.py", line 667, in send
    resp = conn.urlopen(
           ^^^^^^^^^^^^^
  File "c:\Users\User\AppData\Local\Programs\Python\Python312\Lib\site-packages\urllib3\connectionpool.py", line 841, in urlopen
    retries = retries.increment(
              ^^^^^^^^^^^^^^^^^^
  File "c:\Users\User\AppData\Local\Programs\Python\Python312\Lib\site-packages\urllib3\util\retry.py", line 519, in increment
    raise MaxRetryError(_pool, url, reason) from reason  # type: ignore[arg-type]
    ^^^^^^^^^^^^^^^^^^^^^^^^^^^^^^^^^^^^^^^^^^^^^^^^^^^
urllib3.exceptions.MaxRetryError: HTTPSConnectionPool(host='api.telegram.org', port=443): Max retries exceeded with url: /bot8120214959:***********************************/getUpdates?offset=1&timeout=20 (Caused by NameResolutionError("<urllib3.connection.HTTPSConnection object at 0x000001851BF9DF70>: Failed to resolve 'api.telegram.org' ([Errno 11001] getaddrinfo failed)"))

During handling of the above exception, another exception occurred:

Traceback (most recent call last):
  File "c:\Users\User\AppData\Local\Programs\Python\Python312\Lib\site-packages\telebot\__init__.py", line 1110, in infinity_polling
    self.polling(non_stop=True, timeout=timeout, long_polling_timeout=long_polling_timeout,
  File "c:\Users\User\AppData\Local\Programs\Python\Python312\Lib\site-packages\telebot\__init__.py", line 1198, in polling
    self.__threaded_polling(non_stop=non_stop, interval=interval, timeout=timeout, long_polling_timeout=long_polling_timeout,
  File "c:\Users\User\AppData\Local\Programs\Python\Python312\Lib\site-packages\telebot\__init__.py", line 1273, in __threaded_polling
    raise e
  File "c:\Users\User\AppData\Local\Programs\Python\Python312\Lib\site-packages\telebot\__init__.py", line 1234, in __threaded_polling
    polling_thread.raise_exceptions()
  File "c:\Users\User\AppData\Local\Programs\Python\Python312\Lib\site-packages\telebot\util.py", line 111, in raise_exceptions
    raise self.exception_info
  File "c:\Users\User\AppData\Local\Programs\Python\Python312\Lib\site-packages\telebot\util.py", line 93, in run
    task(*args, **kwargs)
  File "c:\Users\User\AppData\Local\Programs\Python\Python312\Lib\site-packages\telebot\__init__.py", line 688, in __retrieve_updates
    updates = self.get_updates(offset=(self.last_update_id + 1),
             ^^^^^^^^^^^^^^^^^^^^^^^^^^^^^^^^^^^^^^^^^^^^^^^^^^
  File "c:\Users\User\AppData\Local\Programs\Python\Python312\Lib\site-packages\telebot\__init__.py", line 660, in get_updates
    json_updates = apihelper.get_updates(
                   ^^^^^^^^^^^^^^^^^^^^^^
  File "c:\Users\User\AppData\Local\Programs\Python\Python312\Lib\site-packages\telebot\apihelper.py", line 332, in get_updates
    return _make_request(token, method_url, params=payload)
           ^^^^^^^^^^^^^^^^^^^^^^^^^^^^^^^^^^^^^^^^^^^^^^^^
  File "c:\Users\User\AppData\Local\Programs\Python\Python312\Lib\site-packages\telebot\apihelper.py", line 162, in _make_request
    result = _get_req_session().request(
             ^^^^^^^^^^^^^^^^^^^^^^^^^^^
  File "c:\Users\User\AppData\Local\Programs\Python\Python312\Lib\site-packages\requests\sessions.py", line 589, in request
    resp = self.send(prep, **send_kwargs)
           ^^^^^^^^^^^^^^^^^^^^^^^^^^^^^^
  File "c:\Users\User\AppData\Local\Programs\Python\Python312\Lib\site-packages\requests\sessions.py", line 703, in send
    r = adapter.send(request, **kwargs)
        ^^^^^^^^^^^^^^^^^^^^^^^^^^^^^^^
  File "c:\Users\User\AppData\Local\Programs\Python\Python312\Lib\site-packages\requests\adapters.py", line 700, in send
    raise ConnectionError(e, request=request)
requests.exceptions.ConnectionError: HTTPSConnectionPool(host='api.telegram.org', port=443): Max retries exceeded with url: /bot8120214959:***********************************/getUpdates?offset=1&timeout=20 (Caused by NameResolutionError("<urllib3.connection.HTTPSConnection object at 0x000001851BF9DF70>: Failed to resolve 'api.telegram.org' ([Errno 11001] getaddrinfo failed)"))

2025-07-23 21:03:20,567 - TeleBot - ERROR - Infinity polling exception: HTTPSConnectionPool(host='api.telegram.org', port=443): Max retries exceeded with url: /bot8120214959:***********************************/getUpdates?offset=1&timeout=20 (Caused by NameResolutionError("<urllib3.connection.HTTPSConnection object at 0x000001851BF3B080>: Failed to resolve 'api.telegram.org' ([Errno 11001] getaddrinfo failed)"))
2025-07-23 21:03:20,569 - TeleBot - ERROR - Exception traceback:
Traceback (most recent call last):
  File "c:\Users\User\AppData\Local\Programs\Python\Python312\Lib\site-packages\urllib3\connection.py", line 198, in _new_conn
    sock = connection.create_connection(
           ^^^^^^^^^^^^^^^^^^^^^^^^^^^^^
  File "c:\Users\User\AppData\Local\Programs\Python\Python312\Lib\site-packages\urllib3\util\connection.py", line 60, in create_connection
    for res in socket.getaddrinfo(host, port, family, socket.SOCK_STREAM):
               ^^^^^^^^^^^^^^^^^^^^^^^^^^^^^^^^^^^^^^^^^^^^^^^^^^^^^^^^^^
  File "c:\Users\User\AppData\Local\Programs\Python\Python312\Lib\socket.py", line 976, in getaddrinfo
    for res in _socket.getaddrinfo(host, port, family, type, proto, flags):
               ^^^^^^^^^^^^^^^^^^^^^^^^^^^^^^^^^^^^^^^^^^^^^^^^^^^^^^^^^^^
socket.gaierror: [Errno 11001] getaddrinfo failed

The above exception was the direct cause of the following exception:

Traceback (most recent call last):
  File "c:\Users\User\AppData\Local\Programs\Python\Python312\Lib\site-packages\urllib3\connectionpool.py", line 787, in urlopen
    response = self._make_request(
               ^^^^^^^^^^^^^^^^^^^
  File "c:\Users\User\AppData\Local\Programs\Python\Python312\Lib\site-packages\urllib3\connectionpool.py", line 488, in _make_request
    raise new_e
  File "c:\Users\User\AppData\Local\Programs\Python\Python312\Lib\site-packages\urllib3\connectionpool.py", line 464, in _make_request
    self._validate_conn(conn)
  File "c:\Users\User\AppData\Local\Programs\Python\Python312\Lib\site-packages\urllib3\connectionpool.py", line 1093, in _validate_conn
    conn.connect()
  File "c:\Users\User\AppData\Local\Programs\Python\Python312\Lib\site-packages\urllib3\connection.py", line 753, in connect
    self.sock = sock = self._new_conn()
                       ^^^^^^^^^^^^^^^^
  File "c:\Users\User\AppData\Local\Programs\Python\Python312\Lib\site-packages\urllib3\connection.py", line 205, in _new_conn
    raise NameResolutionError(self.host, self, e) from e
urllib3.exceptions.NameResolutionError: <urllib3.connection.HTTPSConnection object at 0x000001851BF3B080>: Failed to resolve 'api.telegram.org' ([Errno 11001] getaddrinfo failed)

The above exception was the direct cause of the following exception:

Traceback (most recent call last):
  File "c:\Users\User\AppData\Local\Programs\Python\Python312\Lib\site-packages\requests\adapters.py", line 667, in send
    resp = conn.urlopen(
           ^^^^^^^^^^^^^
  File "c:\Users\User\AppData\Local\Programs\Python\Python312\Lib\site-packages\urllib3\connectionpool.py", line 841, in urlopen
    retries = retries.increment(
              ^^^^^^^^^^^^^^^^^^
  File "c:\Users\User\AppData\Local\Programs\Python\Python312\Lib\site-packages\urllib3\util\retry.py", line 519, in increment
    raise MaxRetryError(_pool, url, reason) from reason  # type: ignore[arg-type]
    ^^^^^^^^^^^^^^^^^^^^^^^^^^^^^^^^^^^^^^^^^^^^^^^^^^^
urllib3.exceptions.MaxRetryError: HTTPSConnectionPool(host='api.telegram.org', port=443): Max retries exceeded with url: /bot8120214959:***********************************/getUpdates?offset=1&timeout=20 (Caused by NameResolutionError("<urllib3.connection.HTTPSConnection object at 0x000001851BF3B080>: Failed to resolve 'api.telegram.org' ([Errno 11001] getaddrinfo failed)"))

During handling of the above exception, another exception occurred:

Traceback (most recent call last):
  File "c:\Users\User\AppData\Local\Programs\Python\Python312\Lib\site-packages\telebot\__init__.py", line 1110, in infinity_polling
    self.polling(non_stop=True, timeout=timeout, long_polling_timeout=long_polling_timeout,
  File "c:\Users\User\AppData\Local\Programs\Python\Python312\Lib\site-packages\telebot\__init__.py", line 1198, in polling
    self.__threaded_polling(non_stop=non_stop, interval=interval, timeout=timeout, long_polling_timeout=long_polling_timeout,
  File "c:\Users\User\AppData\Local\Programs\Python\Python312\Lib\site-packages\telebot\__init__.py", line 1273, in __threaded_polling
    raise e
  File "c:\Users\User\AppData\Local\Programs\Python\Python312\Lib\site-packages\telebot\__init__.py", line 1234, in __threaded_polling
    polling_thread.raise_exceptions()
  File "c:\Users\User\AppData\Local\Programs\Python\Python312\Lib\site-packages\telebot\util.py", line 111, in raise_exceptions
    raise self.exception_info
  File "c:\Users\User\AppData\Local\Programs\Python\Python312\Lib\site-packages\telebot\util.py", line 93, in run
    task(*args, **kwargs)
  File "c:\Users\User\AppData\Local\Programs\Python\Python312\Lib\site-packages\telebot\__init__.py", line 688, in __retrieve_updates
    updates = self.get_updates(offset=(self.last_update_id + 1),
             ^^^^^^^^^^^^^^^^^^^^^^^^^^^^^^^^^^^^^^^^^^^^^^^^^^
  File "c:\Users\User\AppData\Local\Programs\Python\Python312\Lib\site-packages\telebot\__init__.py", line 660, in get_updates
    json_updates = apihelper.get_updates(
                   ^^^^^^^^^^^^^^^^^^^^^^
  File "c:\Users\User\AppData\Local\Programs\Python\Python312\Lib\site-packages\telebot\apihelper.py", line 332, in get_updates
    return _make_request(token, method_url, params=payload)
           ^^^^^^^^^^^^^^^^^^^^^^^^^^^^^^^^^^^^^^^^^^^^^^^^
  File "c:\Users\User\AppData\Local\Programs\Python\Python312\Lib\site-packages\telebot\apihelper.py", line 162, in _make_request
    result = _get_req_session().request(
             ^^^^^^^^^^^^^^^^^^^^^^^^^^^
  File "c:\Users\User\AppData\Local\Programs\Python\Python312\Lib\site-packages\requests\sessions.py", line 589, in request
    resp = self.send(prep, **send_kwargs)
           ^^^^^^^^^^^^^^^^^^^^^^^^^^^^^^
  File "c:\Users\User\AppData\Local\Programs\Python\Python312\Lib\site-packages\requests\sessions.py", line 703, in send
    r = adapter.send(request, **kwargs)
        ^^^^^^^^^^^^^^^^^^^^^^^^^^^^^^^
  File "c:\Users\User\AppData\Local\Programs\Python\Python312\Lib\site-packages\requests\adapters.py", line 700, in send
    raise ConnectionError(e, request=request)
requests.exceptions.ConnectionError: HTTPSConnectionPool(host='api.telegram.org', port=443): Max retries exceeded with url: /bot8120214959:***********************************/getUpdates?offset=1&timeout=20 (Caused by NameResolutionError("<urllib3.connection.HTTPSConnection object at 0x000001851BF3B080>: Failed to resolve 'api.telegram.org' ([Errno 11001] getaddrinfo failed)"))

2025-07-23 21:03:23,587 - TeleBot - ERROR - Infinity polling exception: HTTPSConnectionPool(host='api.telegram.org', port=443): Max retries exceeded with url: /bot8120214959:***********************************/getUpdates?offset=1&timeout=20 (Caused by NameResolutionError("<urllib3.connection.HTTPSConnection object at 0x000001851C4697F0>: Failed to resolve 'api.telegram.org' ([Errno 11001] getaddrinfo failed)"))
2025-07-23 21:03:23,633 - TeleBot - ERROR - Exception traceback:
Traceback (most recent call last):
  File "c:\Users\User\AppData\Local\Programs\Python\Python312\Lib\site-packages\urllib3\connection.py", line 198, in _new_conn
    sock = connection.create_connection(
           ^^^^^^^^^^^^^^^^^^^^^^^^^^^^^
  File "c:\Users\User\AppData\Local\Programs\Python\Python312\Lib\site-packages\urllib3\util\connection.py", line 60, in create_connection
    for res in socket.getaddrinfo(host, port, family, socket.SOCK_STREAM):
               ^^^^^^^^^^^^^^^^^^^^^^^^^^^^^^^^^^^^^^^^^^^^^^^^^^^^^^^^^^
  File "c:\Users\User\AppData\Local\Programs\Python\Python312\Lib\socket.py", line 976, in getaddrinfo
    for res in _socket.getaddrinfo(host, port, family, type, proto, flags):
               ^^^^^^^^^^^^^^^^^^^^^^^^^^^^^^^^^^^^^^^^^^^^^^^^^^^^^^^^^^^
socket.gaierror: [Errno 11001] getaddrinfo failed

The above exception was the direct cause of the following exception:

Traceback (most recent call last):
  File "c:\Users\User\AppData\Local\Programs\Python\Python312\Lib\site-packages\urllib3\connectionpool.py", line 787, in urlopen
    response = self._make_request(
               ^^^^^^^^^^^^^^^^^^^
  File "c:\Users\User\AppData\Local\Programs\Python\Python312\Lib\site-packages\urllib3\connectionpool.py", line 488, in _make_request
    raise new_e
  File "c:\Users\User\AppData\Local\Programs\Python\Python312\Lib\site-packages\urllib3\connectionpool.py", line 464, in _make_request
    self._validate_conn(conn)
  File "c:\Users\User\AppData\Local\Programs\Python\Python312\Lib\site-packages\urllib3\connectionpool.py", line 1093, in _validate_conn
    conn.connect()
  File "c:\Users\User\AppData\Local\Programs\Python\Python312\Lib\site-packages\urllib3\connection.py", line 753, in connect
    self.sock = sock = self._new_conn()
                       ^^^^^^^^^^^^^^^^
  File "c:\Users\User\AppData\Local\Programs\Python\Python312\Lib\site-packages\urllib3\connection.py", line 205, in _new_conn
    raise NameResolutionError(self.host, self, e) from e
urllib3.exceptions.NameResolutionError: <urllib3.connection.HTTPSConnection object at 0x000001851C4697F0>: Failed to resolve 'api.telegram.org' ([Errno 11001] getaddrinfo failed)

The above exception was the direct cause of the following exception:

Traceback (most recent call last):
  File "c:\Users\User\AppData\Local\Programs\Python\Python312\Lib\site-packages\requests\adapters.py", line 667, in send
    resp = conn.urlopen(
           ^^^^^^^^^^^^^
  File "c:\Users\User\AppData\Local\Programs\Python\Python312\Lib\site-packages\urllib3\connectionpool.py", line 841, in urlopen
    retries = retries.increment(
              ^^^^^^^^^^^^^^^^^^
  File "c:\Users\User\AppData\Local\Programs\Python\Python312\Lib\site-packages\urllib3\util\retry.py", line 519, in increment
    raise MaxRetryError(_pool, url, reason) from reason  # type: ignore[arg-type]
    ^^^^^^^^^^^^^^^^^^^^^^^^^^^^^^^^^^^^^^^^^^^^^^^^^^^
urllib3.exceptions.MaxRetryError: HTTPSConnectionPool(host='api.telegram.org', port=443): Max retries exceeded with url: /bot8120214959:***********************************/getUpdates?offset=1&timeout=20 (Caused by NameResolutionError("<urllib3.connection.HTTPSConnection object at 0x000001851C4697F0>: Failed to resolve 'api.telegram.org' ([Errno 11001] getaddrinfo failed)"))

During handling of the above exception, another exception occurred:

Traceback (most recent call last):
  File "c:\Users\User\AppData\Local\Programs\Python\Python312\Lib\site-packages\telebot\__init__.py", line 1110, in infinity_polling
    self.polling(non_stop=True, timeout=timeout, long_polling_timeout=long_polling_timeout,
  File "c:\Users\User\AppData\Local\Programs\Python\Python312\Lib\site-packages\telebot\__init__.py", line 1198, in polling
    self.__threaded_polling(non_stop=non_stop, interval=interval, timeout=timeout, long_polling_timeout=long_polling_timeout,
  File "c:\Users\User\AppData\Local\Programs\Python\Python312\Lib\site-packages\telebot\__init__.py", line 1273, in __threaded_polling
    raise e
  File "c:\Users\User\AppData\Local\Programs\Python\Python312\Lib\site-packages\telebot\__init__.py", line 1234, in __threaded_polling
    polling_thread.raise_exceptions()
  File "c:\Users\User\AppData\Local\Programs\Python\Python312\Lib\site-packages\telebot\util.py", line 111, in raise_exceptions
    raise self.exception_info
  File "c:\Users\User\AppData\Local\Programs\Python\Python312\Lib\site-packages\telebot\util.py", line 93, in run
    task(*args, **kwargs)
  File "c:\Users\User\AppData\Local\Programs\Python\Python312\Lib\site-packages\telebot\__init__.py", line 688, in __retrieve_updates
    updates = self.get_updates(offset=(self.last_update_id + 1),
             ^^^^^^^^^^^^^^^^^^^^^^^^^^^^^^^^^^^^^^^^^^^^^^^^^^
  File "c:\Users\User\AppData\Local\Programs\Python\Python312\Lib\site-packages\telebot\__init__.py", line 660, in get_updates
    json_updates = apihelper.get_updates(
                   ^^^^^^^^^^^^^^^^^^^^^^
  File "c:\Users\User\AppData\Local\Programs\Python\Python312\Lib\site-packages\telebot\apihelper.py", line 332, in get_updates
    return _make_request(token, method_url, params=payload)
           ^^^^^^^^^^^^^^^^^^^^^^^^^^^^^^^^^^^^^^^^^^^^^^^^
  File "c:\Users\User\AppData\Local\Programs\Python\Python312\Lib\site-packages\telebot\apihelper.py", line 162, in _make_request
    result = _get_req_session().request(
             ^^^^^^^^^^^^^^^^^^^^^^^^^^^
  File "c:\Users\User\AppData\Local\Programs\Python\Python312\Lib\site-packages\requests\sessions.py", line 589, in request
    resp = self.send(prep, **send_kwargs)
           ^^^^^^^^^^^^^^^^^^^^^^^^^^^^^^
  File "c:\Users\User\AppData\Local\Programs\Python\Python312\Lib\site-packages\requests\sessions.py", line 703, in send
    r = adapter.send(request, **kwargs)
        ^^^^^^^^^^^^^^^^^^^^^^^^^^^^^^^
  File "c:\Users\User\AppData\Local\Programs\Python\Python312\Lib\site-packages\requests\adapters.py", line 700, in send
    raise ConnectionError(e, request=request)
requests.exceptions.ConnectionError: HTTPSConnectionPool(host='api.telegram.org', port=443): Max retries exceeded with url: /bot8120214959:***********************************/getUpdates?offset=1&timeout=20 (Caused by NameResolutionError("<urllib3.connection.HTTPSConnection object at 0x000001851C4697F0>: Failed to resolve 'api.telegram.org' ([Errno 11001] getaddrinfo failed)"))

2025-07-23 21:03:26,653 - TeleBot - ERROR - Infinity polling exception: HTTPSConnectionPool(host='api.telegram.org', port=443): Max retries exceeded with url: /bot8120214959:***********************************/getUpdates?offset=1&timeout=20 (Caused by NameResolutionError("<urllib3.connection.HTTPSConnection object at 0x000001851BF9F2C0>: Failed to resolve 'api.telegram.org' ([Errno 11001] getaddrinfo failed)"))
2025-07-23 21:03:26,674 - TeleBot - ERROR - Exception traceback:
Traceback (most recent call last):
  File "c:\Users\User\AppData\Local\Programs\Python\Python312\Lib\site-packages\urllib3\connection.py", line 198, in _new_conn
    sock = connection.create_connection(
           ^^^^^^^^^^^^^^^^^^^^^^^^^^^^^
  File "c:\Users\User\AppData\Local\Programs\Python\Python312\Lib\site-packages\urllib3\util\connection.py", line 60, in create_connection
    for res in socket.getaddrinfo(host, port, family, socket.SOCK_STREAM):
               ^^^^^^^^^^^^^^^^^^^^^^^^^^^^^^^^^^^^^^^^^^^^^^^^^^^^^^^^^^
  File "c:\Users\User\AppData\Local\Programs\Python\Python312\Lib\socket.py", line 976, in getaddrinfo
    for res in _socket.getaddrinfo(host, port, family, type, proto, flags):
               ^^^^^^^^^^^^^^^^^^^^^^^^^^^^^^^^^^^^^^^^^^^^^^^^^^^^^^^^^^^
socket.gaierror: [Errno 11001] getaddrinfo failed

The above exception was the direct cause of the following exception:

Traceback (most recent call last):
  File "c:\Users\User\AppData\Local\Programs\Python\Python312\Lib\site-packages\urllib3\connectionpool.py", line 787, in urlopen
    response = self._make_request(
               ^^^^^^^^^^^^^^^^^^^
  File "c:\Users\User\AppData\Local\Programs\Python\Python312\Lib\site-packages\urllib3\connectionpool.py", line 488, in _make_request
    raise new_e
  File "c:\Users\User\AppData\Local\Programs\Python\Python312\Lib\site-packages\urllib3\connectionpool.py", line 464, in _make_request
    self._validate_conn(conn)
  File "c:\Users\User\AppData\Local\Programs\Python\Python312\Lib\site-packages\urllib3\connectionpool.py", line 1093, in _validate_conn
    conn.connect()
  File "c:\Users\User\AppData\Local\Programs\Python\Python312\Lib\site-packages\urllib3\connection.py", line 753, in connect
    self.sock = sock = self._new_conn()
                       ^^^^^^^^^^^^^^^^
  File "c:\Users\User\AppData\Local\Programs\Python\Python312\Lib\site-packages\urllib3\connection.py", line 205, in _new_conn
    raise NameResolutionError(self.host, self, e) from e
urllib3.exceptions.NameResolutionError: <urllib3.connection.HTTPSConnection object at 0x000001851BF9F2C0>: Failed to resolve 'api.telegram.org' ([Errno 11001] getaddrinfo failed)

The above exception was the direct cause of the following exception:

Traceback (most recent call last):
  File "c:\Users\User\AppData\Local\Programs\Python\Python312\Lib\site-packages\requests\adapters.py", line 667, in send
    resp = conn.urlopen(
           ^^^^^^^^^^^^^
  File "c:\Users\User\AppData\Local\Programs\Python\Python312\Lib\site-packages\urllib3\connectionpool.py", line 841, in urlopen
    retries = retries.increment(
              ^^^^^^^^^^^^^^^^^^
  File "c:\Users\User\AppData\Local\Programs\Python\Python312\Lib\site-packages\urllib3\util\retry.py", line 519, in increment
    raise MaxRetryError(_pool, url, reason) from reason  # type: ignore[arg-type]
    ^^^^^^^^^^^^^^^^^^^^^^^^^^^^^^^^^^^^^^^^^^^^^^^^^^^
urllib3.exceptions.MaxRetryError: HTTPSConnectionPool(host='api.telegram.org', port=443): Max retries exceeded with url: /bot8120214959:***********************************/getUpdates?offset=1&timeout=20 (Caused by NameResolutionError("<urllib3.connection.HTTPSConnection object at 0x000001851BF9F2C0>: Failed to resolve 'api.telegram.org' ([Errno 11001] getaddrinfo failed)"))

During handling of the above exception, another exception occurred:

Traceback (most recent call last):
  File "c:\Users\User\AppData\Local\Programs\Python\Python312\Lib\site-packages\telebot\__init__.py", line 1110, in infinity_polling
    self.polling(non_stop=True, timeout=timeout, long_polling_timeout=long_polling_timeout,
  File "c:\Users\User\AppData\Local\Programs\Python\Python312\Lib\site-packages\telebot\__init__.py", line 1198, in polling
    self.__threaded_polling(non_stop=non_stop, interval=interval, timeout=timeout, long_polling_timeout=long_polling_timeout,
  File "c:\Users\User\AppData\Local\Programs\Python\Python312\Lib\site-packages\telebot\__init__.py", line 1273, in __threaded_polling
    raise e
  File "c:\Users\User\AppData\Local\Programs\Python\Python312\Lib\site-packages\telebot\__init__.py", line 1234, in __threaded_polling
    polling_thread.raise_exceptions()
  File "c:\Users\User\AppData\Local\Programs\Python\Python312\Lib\site-packages\telebot\util.py", line 111, in raise_exceptions
    raise self.exception_info
  File "c:\Users\User\AppData\Local\Programs\Python\Python312\Lib\site-packages\telebot\util.py", line 93, in run
    task(*args, **kwargs)
  File "c:\Users\User\AppData\Local\Programs\Python\Python312\Lib\site-packages\telebot\__init__.py", line 688, in __retrieve_updates
    updates = self.get_updates(offset=(self.last_update_id + 1),
             ^^^^^^^^^^^^^^^^^^^^^^^^^^^^^^^^^^^^^^^^^^^^^^^^^^
  File "c:\Users\User\AppData\Local\Programs\Python\Python312\Lib\site-packages\telebot\__init__.py", line 660, in get_updates
    json_updates = apihelper.get_updates(
                   ^^^^^^^^^^^^^^^^^^^^^^
  File "c:\Users\User\AppData\Local\Programs\Python\Python312\Lib\site-packages\telebot\apihelper.py", line 332, in get_updates
    return _make_request(token, method_url, params=payload)
           ^^^^^^^^^^^^^^^^^^^^^^^^^^^^^^^^^^^^^^^^^^^^^^^^
  File "c:\Users\User\AppData\Local\Programs\Python\Python312\Lib\site-packages\telebot\apihelper.py", line 162, in _make_request
    result = _get_req_session().request(
             ^^^^^^^^^^^^^^^^^^^^^^^^^^^
  File "c:\Users\User\AppData\Local\Programs\Python\Python312\Lib\site-packages\requests\sessions.py", line 589, in request
    resp = self.send(prep, **send_kwargs)
           ^^^^^^^^^^^^^^^^^^^^^^^^^^^^^^
  File "c:\Users\User\AppData\Local\Programs\Python\Python312\Lib\site-packages\requests\sessions.py", line 703, in send
    r = adapter.send(request, **kwargs)
        ^^^^^^^^^^^^^^^^^^^^^^^^^^^^^^^
  File "c:\Users\User\AppData\Local\Programs\Python\Python312\Lib\site-packages\requests\adapters.py", line 700, in send
    raise ConnectionError(e, request=request)
requests.exceptions.ConnectionError: HTTPSConnectionPool(host='api.telegram.org', port=443): Max retries exceeded with url: /bot8120214959:***********************************/getUpdates?offset=1&timeout=20 (Caused by NameResolutionError("<urllib3.connection.HTTPSConnection object at 0x000001851BF9F2C0>: Failed to resolve 'api.telegram.org' ([Errno 11001] getaddrinfo failed)"))

2025-07-23 21:03:29,691 - TeleBot - ERROR - Infinity polling exception: HTTPSConnectionPool(host='api.telegram.org', port=443): Max retries exceeded with url: /bot8120214959:***********************************/getUpdates?offset=1&timeout=20 (Caused by NameResolutionError("<urllib3.connection.HTTPSConnection object at 0x000001851C468F20>: Failed to resolve 'api.telegram.org' ([Errno 11001] getaddrinfo failed)"))
2025-07-23 21:03:29,705 - TeleBot - ERROR - Exception traceback:
Traceback (most recent call last):
  File "c:\Users\User\AppData\Local\Programs\Python\Python312\Lib\site-packages\urllib3\connection.py", line 198, in _new_conn
    sock = connection.create_connection(
           ^^^^^^^^^^^^^^^^^^^^^^^^^^^^^
  File "c:\Users\User\AppData\Local\Programs\Python\Python312\Lib\site-packages\urllib3\util\connection.py", line 60, in create_connection
    for res in socket.getaddrinfo(host, port, family, socket.SOCK_STREAM):
               ^^^^^^^^^^^^^^^^^^^^^^^^^^^^^^^^^^^^^^^^^^^^^^^^^^^^^^^^^^
  File "c:\Users\User\AppData\Local\Programs\Python\Python312\Lib\socket.py", line 976, in getaddrinfo
    for res in _socket.getaddrinfo(host, port, family, type, proto, flags):
               ^^^^^^^^^^^^^^^^^^^^^^^^^^^^^^^^^^^^^^^^^^^^^^^^^^^^^^^^^^^
socket.gaierror: [Errno 11001] getaddrinfo failed

The above exception was the direct cause of the following exception:

Traceback (most recent call last):
  File "c:\Users\User\AppData\Local\Programs\Python\Python312\Lib\site-packages\urllib3\connectionpool.py", line 787, in urlopen
    response = self._make_request(
               ^^^^^^^^^^^^^^^^^^^
  File "c:\Users\User\AppData\Local\Programs\Python\Python312\Lib\site-packages\urllib3\connectionpool.py", line 488, in _make_request
    raise new_e
  File "c:\Users\User\AppData\Local\Programs\Python\Python312\Lib\site-packages\urllib3\connectionpool.py", line 464, in _make_request
    self._validate_conn(conn)
  File "c:\Users\User\AppData\Local\Programs\Python\Python312\Lib\site-packages\urllib3\connectionpool.py", line 1093, in _validate_conn
    conn.connect()
  File "c:\Users\User\AppData\Local\Programs\Python\Python312\Lib\site-packages\urllib3\connection.py", line 753, in connect
    self.sock = sock = self._new_conn()
                       ^^^^^^^^^^^^^^^^
  File "c:\Users\User\AppData\Local\Programs\Python\Python312\Lib\site-packages\urllib3\connection.py", line 205, in _new_conn
    raise NameResolutionError(self.host, self, e) from e
urllib3.exceptions.NameResolutionError: <urllib3.connection.HTTPSConnection object at 0x000001851C468F20>: Failed to resolve 'api.telegram.org' ([Errno 11001] getaddrinfo failed)

The above exception was the direct cause of the following exception:

Traceback (most recent call last):
  File "c:\Users\User\AppData\Local\Programs\Python\Python312\Lib\site-packages\requests\adapters.py", line 667, in send
    resp = conn.urlopen(
           ^^^^^^^^^^^^^
  File "c:\Users\User\AppData\Local\Programs\Python\Python312\Lib\site-packages\urllib3\connectionpool.py", line 841, in urlopen
    retries = retries.increment(
              ^^^^^^^^^^^^^^^^^^
  File "c:\Users\User\AppData\Local\Programs\Python\Python312\Lib\site-packages\urllib3\util\retry.py", line 519, in increment
    raise MaxRetryError(_pool, url, reason) from reason  # type: ignore[arg-type]
    ^^^^^^^^^^^^^^^^^^^^^^^^^^^^^^^^^^^^^^^^^^^^^^^^^^^
urllib3.exceptions.MaxRetryError: HTTPSConnectionPool(host='api.telegram.org', port=443): Max retries exceeded with url: /bot8120214959:***********************************/getUpdates?offset=1&timeout=20 (Caused by NameResolutionError("<urllib3.connection.HTTPSConnection object at 0x000001851C468F20>: Failed to resolve 'api.telegram.org' ([Errno 11001] getaddrinfo failed)"))

During handling of the above exception, another exception occurred:

Traceback (most recent call last):
  File "c:\Users\User\AppData\Local\Programs\Python\Python312\Lib\site-packages\telebot\__init__.py", line 1110, in infinity_polling
    self.polling(non_stop=True, timeout=timeout, long_polling_timeout=long_polling_timeout,
  File "c:\Users\User\AppData\Local\Programs\Python\Python312\Lib\site-packages\telebot\__init__.py", line 1198, in polling
    self.__threaded_polling(non_stop=non_stop, interval=interval, timeout=timeout, long_polling_timeout=long_polling_timeout,
  File "c:\Users\User\AppData\Local\Programs\Python\Python312\Lib\site-packages\telebot\__init__.py", line 1273, in __threaded_polling
    raise e
  File "c:\Users\User\AppData\Local\Programs\Python\Python312\Lib\site-packages\telebot\__init__.py", line 1234, in __threaded_polling
    polling_thread.raise_exceptions()
  File "c:\Users\User\AppData\Local\Programs\Python\Python312\Lib\site-packages\telebot\util.py", line 111, in raise_exceptions
    raise self.exception_info
  File "c:\Users\User\AppData\Local\Programs\Python\Python312\Lib\site-packages\telebot\util.py", line 93, in run
    task(*args, **kwargs)
  File "c:\Users\User\AppData\Local\Programs\Python\Python312\Lib\site-packages\telebot\__init__.py", line 688, in __retrieve_updates
    updates = self.get_updates(offset=(self.last_update_id + 1),
             ^^^^^^^^^^^^^^^^^^^^^^^^^^^^^^^^^^^^^^^^^^^^^^^^^^
  File "c:\Users\User\AppData\Local\Programs\Python\Python312\Lib\site-packages\telebot\__init__.py", line 660, in get_updates
    json_updates = apihelper.get_updates(
                   ^^^^^^^^^^^^^^^^^^^^^^
  File "c:\Users\User\AppData\Local\Programs\Python\Python312\Lib\site-packages\telebot\apihelper.py", line 332, in get_updates
    return _make_request(token, method_url, params=payload)
           ^^^^^^^^^^^^^^^^^^^^^^^^^^^^^^^^^^^^^^^^^^^^^^^^
  File "c:\Users\User\AppData\Local\Programs\Python\Python312\Lib\site-packages\telebot\apihelper.py", line 162, in _make_request
    result = _get_req_session().request(
             ^^^^^^^^^^^^^^^^^^^^^^^^^^^
  File "c:\Users\User\AppData\Local\Programs\Python\Python312\Lib\site-packages\requests\sessions.py", line 589, in request
    resp = self.send(prep, **send_kwargs)
           ^^^^^^^^^^^^^^^^^^^^^^^^^^^^^^
  File "c:\Users\User\AppData\Local\Programs\Python\Python312\Lib\site-packages\requests\sessions.py", line 703, in send
    r = adapter.send(request, **kwargs)
        ^^^^^^^^^^^^^^^^^^^^^^^^^^^^^^^
  File "c:\Users\User\AppData\Local\Programs\Python\Python312\Lib\site-packages\requests\adapters.py", line 700, in send
    raise ConnectionError(e, request=request)
requests.exceptions.ConnectionError: HTTPSConnectionPool(host='api.telegram.org', port=443): Max retries exceeded with url: /bot8120214959:***********************************/getUpdates?offset=1&timeout=20 (Caused by NameResolutionError("<urllib3.connection.HTTPSConnection object at 0x000001851C468F20>: Failed to resolve 'api.telegram.org' ([Errno 11001] getaddrinfo failed)"))

2025-07-23 21:03:32,769 - TeleBot - ERROR - Infinity polling exception: HTTPSConnectionPool(host='api.telegram.org', port=443): Max retries exceeded with url: /bot8120214959:***********************************/getUpdates?offset=1&timeout=20 (Caused by NameResolutionError("<urllib3.connection.HTTPSConnection object at 0x000001851C46A9F0>: Failed to resolve 'api.telegram.org' ([Errno 11001] getaddrinfo failed)"))
2025-07-23 21:03:32,778 - TeleBot - ERROR - Exception traceback:
Traceback (most recent call last):
  File "c:\Users\User\AppData\Local\Programs\Python\Python312\Lib\site-packages\urllib3\connection.py", line 198, in _new_conn
    sock = connection.create_connection(
           ^^^^^^^^^^^^^^^^^^^^^^^^^^^^^
  File "c:\Users\User\AppData\Local\Programs\Python\Python312\Lib\site-packages\urllib3\util\connection.py", line 60, in create_connection
    for res in socket.getaddrinfo(host, port, family, socket.SOCK_STREAM):
               ^^^^^^^^^^^^^^^^^^^^^^^^^^^^^^^^^^^^^^^^^^^^^^^^^^^^^^^^^^
  File "c:\Users\User\AppData\Local\Programs\Python\Python312\Lib\socket.py", line 976, in getaddrinfo
    for res in _socket.getaddrinfo(host, port, family, type, proto, flags):
               ^^^^^^^^^^^^^^^^^^^^^^^^^^^^^^^^^^^^^^^^^^^^^^^^^^^^^^^^^^^
socket.gaierror: [Errno 11001] getaddrinfo failed

The above exception was the direct cause of the following exception:

Traceback (most recent call last):
  File "c:\Users\User\AppData\Local\Programs\Python\Python312\Lib\site-packages\urllib3\connectionpool.py", line 787, in urlopen
    response = self._make_request(
               ^^^^^^^^^^^^^^^^^^^
  File "c:\Users\User\AppData\Local\Programs\Python\Python312\Lib\site-packages\urllib3\connectionpool.py", line 488, in _make_request
    raise new_e
  File "c:\Users\User\AppData\Local\Programs\Python\Python312\Lib\site-packages\urllib3\connectionpool.py", line 464, in _make_request
    self._validate_conn(conn)
  File "c:\Users\User\AppData\Local\Programs\Python\Python312\Lib\site-packages\urllib3\connectionpool.py", line 1093, in _validate_conn
    conn.connect()
  File "c:\Users\User\AppData\Local\Programs\Python\Python312\Lib\site-packages\urllib3\connection.py", line 753, in connect
    self.sock = sock = self._new_conn()
                       ^^^^^^^^^^^^^^^^
  File "c:\Users\User\AppData\Local\Programs\Python\Python312\Lib\site-packages\urllib3\connection.py", line 205, in _new_conn
    raise NameResolutionError(self.host, self, e) from e
urllib3.exceptions.NameResolutionError: <urllib3.connection.HTTPSConnection object at 0x000001851C46A9F0>: Failed to resolve 'api.telegram.org' ([Errno 11001] getaddrinfo failed)

The above exception was the direct cause of the following exception:

Traceback (most recent call last):
  File "c:\Users\User\AppData\Local\Programs\Python\Python312\Lib\site-packages\requests\adapters.py", line 667, in send
    resp = conn.urlopen(
           ^^^^^^^^^^^^^
  File "c:\Users\User\AppData\Local\Programs\Python\Python312\Lib\site-packages\urllib3\connectionpool.py", line 841, in urlopen
    retries = retries.increment(
              ^^^^^^^^^^^^^^^^^^
  File "c:\Users\User\AppData\Local\Programs\Python\Python312\Lib\site-packages\urllib3\util\retry.py", line 519, in increment
    raise MaxRetryError(_pool, url, reason) from reason  # type: ignore[arg-type]
    ^^^^^^^^^^^^^^^^^^^^^^^^^^^^^^^^^^^^^^^^^^^^^^^^^^^
urllib3.exceptions.MaxRetryError: HTTPSConnectionPool(host='api.telegram.org', port=443): Max retries exceeded with url: /bot8120214959:***********************************/getUpdates?offset=1&timeout=20 (Caused by NameResolutionError("<urllib3.connection.HTTPSConnection object at 0x000001851C46A9F0>: Failed to resolve 'api.telegram.org' ([Errno 11001] getaddrinfo failed)"))

During handling of the above exception, another exception occurred:

Traceback (most recent call last):
  File "c:\Users\User\AppData\Local\Programs\Python\Python312\Lib\site-packages\telebot\__init__.py", line 1110, in infinity_polling
    self.polling(non_stop=True, timeout=timeout, long_polling_timeout=long_polling_timeout,
  File "c:\Users\User\AppData\Local\Programs\Python\Python312\Lib\site-packages\telebot\__init__.py", line 1198, in polling
    self.__threaded_polling(non_stop=non_stop, interval=interval, timeout=timeout, long_polling_timeout=long_polling_timeout,
  File "c:\Users\User\AppData\Local\Programs\Python\Python312\Lib\site-packages\telebot\__init__.py", line 1273, in __threaded_polling
    raise e
  File "c:\Users\User\AppData\Local\Programs\Python\Python312\Lib\site-packages\telebot\__init__.py", line 1234, in __threaded_polling
    polling_thread.raise_exceptions()
  File "c:\Users\User\AppData\Local\Programs\Python\Python312\Lib\site-packages\telebot\util.py", line 111, in raise_exceptions
    raise self.exception_info
  File "c:\Users\User\AppData\Local\Programs\Python\Python312\Lib\site-packages\telebot\util.py", line 93, in run
    task(*args, **kwargs)
  File "c:\Users\User\AppData\Local\Programs\Python\Python312\Lib\site-packages\telebot\__init__.py", line 688, in __retrieve_updates
    updates = self.get_updates(offset=(self.last_update_id + 1),
             ^^^^^^^^^^^^^^^^^^^^^^^^^^^^^^^^^^^^^^^^^^^^^^^^^^
  File "c:\Users\User\AppData\Local\Programs\Python\Python312\Lib\site-packages\telebot\__init__.py", line 660, in get_updates
    json_updates = apihelper.get_updates(
                   ^^^^^^^^^^^^^^^^^^^^^^
  File "c:\Users\User\AppData\Local\Programs\Python\Python312\Lib\site-packages\telebot\apihelper.py", line 332, in get_updates
    return _make_request(token, method_url, params=payload)
           ^^^^^^^^^^^^^^^^^^^^^^^^^^^^^^^^^^^^^^^^^^^^^^^^
  File "c:\Users\User\AppData\Local\Programs\Python\Python312\Lib\site-packages\telebot\apihelper.py", line 162, in _make_request
    result = _get_req_session().request(
             ^^^^^^^^^^^^^^^^^^^^^^^^^^^
  File "c:\Users\User\AppData\Local\Programs\Python\Python312\Lib\site-packages\requests\sessions.py", line 589, in request
    resp = self.send(prep, **send_kwargs)
           ^^^^^^^^^^^^^^^^^^^^^^^^^^^^^^
  File "c:\Users\User\AppData\Local\Programs\Python\Python312\Lib\site-packages\requests\sessions.py", line 703, in send
    r = adapter.send(request, **kwargs)
        ^^^^^^^^^^^^^^^^^^^^^^^^^^^^^^^
  File "c:\Users\User\AppData\Local\Programs\Python\Python312\Lib\site-packages\requests\adapters.py", line 700, in send
    raise ConnectionError(e, request=request)
requests.exceptions.ConnectionError: HTTPSConnectionPool(host='api.telegram.org', port=443): Max retries exceeded with url: /bot8120214959:***********************************/getUpdates?offset=1&timeout=20 (Caused by NameResolutionError("<urllib3.connection.HTTPSConnection object at 0x000001851C46A9F0>: Failed to resolve 'api.telegram.org' ([Errno 11001] getaddrinfo failed)"))

2025-07-23 21:03:35,826 - TeleBot - ERROR - Infinity polling exception: HTTPSConnectionPool(host='api.telegram.org', port=443): Max retries exceeded with url: /bot8120214959:***********************************/getUpdates?offset=1&timeout=20 (Caused by NameResolutionError("<urllib3.connection.HTTPSConnection object at 0x000001851BF9EB10>: Failed to resolve 'api.telegram.org' ([Errno 11001] getaddrinfo failed)"))
2025-07-23 21:03:35,839 - TeleBot - ERROR - Exception traceback:
Traceback (most recent call last):
  File "c:\Users\User\AppData\Local\Programs\Python\Python312\Lib\site-packages\urllib3\connection.py", line 198, in _new_conn
    sock = connection.create_connection(
           ^^^^^^^^^^^^^^^^^^^^^^^^^^^^^
  File "c:\Users\User\AppData\Local\Programs\Python\Python312\Lib\site-packages\urllib3\util\connection.py", line 60, in create_connection
    for res in socket.getaddrinfo(host, port, family, socket.SOCK_STREAM):
               ^^^^^^^^^^^^^^^^^^^^^^^^^^^^^^^^^^^^^^^^^^^^^^^^^^^^^^^^^^
  File "c:\Users\User\AppData\Local\Programs\Python\Python312\Lib\socket.py", line 976, in getaddrinfo
    for res in _socket.getaddrinfo(host, port, family, type, proto, flags):
               ^^^^^^^^^^^^^^^^^^^^^^^^^^^^^^^^^^^^^^^^^^^^^^^^^^^^^^^^^^^
socket.gaierror: [Errno 11001] getaddrinfo failed

The above exception was the direct cause of the following exception:

Traceback (most recent call last):
  File "c:\Users\User\AppData\Local\Programs\Python\Python312\Lib\site-packages\urllib3\connectionpool.py", line 787, in urlopen
    response = self._make_request(
               ^^^^^^^^^^^^^^^^^^^
  File "c:\Users\User\AppData\Local\Programs\Python\Python312\Lib\site-packages\urllib3\connectionpool.py", line 488, in _make_request
    raise new_e
  File "c:\Users\User\AppData\Local\Programs\Python\Python312\Lib\site-packages\urllib3\connectionpool.py", line 464, in _make_request
    self._validate_conn(conn)
  File "c:\Users\User\AppData\Local\Programs\Python\Python312\Lib\site-packages\urllib3\connectionpool.py", line 1093, in _validate_conn
    conn.connect()
  File "c:\Users\User\AppData\Local\Programs\Python\Python312\Lib\site-packages\urllib3\connection.py", line 753, in connect
    self.sock = sock = self._new_conn()
                       ^^^^^^^^^^^^^^^^
  File "c:\Users\User\AppData\Local\Programs\Python\Python312\Lib\site-packages\urllib3\connection.py", line 205, in _new_conn
    raise NameResolutionError(self.host, self, e) from e
urllib3.exceptions.NameResolutionError: <urllib3.connection.HTTPSConnection object at 0x000001851BF9EB10>: Failed to resolve 'api.telegram.org' ([Errno 11001] getaddrinfo failed)

The above exception was the direct cause of the following exception:

Traceback (most recent call last):
  File "c:\Users\User\AppData\Local\Programs\Python\Python312\Lib\site-packages\requests\adapters.py", line 667, in send
    resp = conn.urlopen(
           ^^^^^^^^^^^^^
  File "c:\Users\User\AppData\Local\Programs\Python\Python312\Lib\site-packages\urllib3\connectionpool.py", line 841, in urlopen
    retries = retries.increment(
              ^^^^^^^^^^^^^^^^^^
  File "c:\Users\User\AppData\Local\Programs\Python\Python312\Lib\site-packages\urllib3\util\retry.py", line 519, in increment
    raise MaxRetryError(_pool, url, reason) from reason  # type: ignore[arg-type]
    ^^^^^^^^^^^^^^^^^^^^^^^^^^^^^^^^^^^^^^^^^^^^^^^^^^^
urllib3.exceptions.MaxRetryError: HTTPSConnectionPool(host='api.telegram.org', port=443): Max retries exceeded with url: /bot8120214959:***********************************/getUpdates?offset=1&timeout=20 (Caused by NameResolutionError("<urllib3.connection.HTTPSConnection object at 0x000001851BF9EB10>: Failed to resolve 'api.telegram.org' ([Errno 11001] getaddrinfo failed)"))

During handling of the above exception, another exception occurred:

Traceback (most recent call last):
  File "c:\Users\User\AppData\Local\Programs\Python\Python312\Lib\site-packages\telebot\__init__.py", line 1110, in infinity_polling
    self.polling(non_stop=True, timeout=timeout, long_polling_timeout=long_polling_timeout,
  File "c:\Users\User\AppData\Local\Programs\Python\Python312\Lib\site-packages\telebot\__init__.py", line 1198, in polling
    self.__threaded_polling(non_stop=non_stop, interval=interval, timeout=timeout, long_polling_timeout=long_polling_timeout,
  File "c:\Users\User\AppData\Local\Programs\Python\Python312\Lib\site-packages\telebot\__init__.py", line 1273, in __threaded_polling
    raise e
  File "c:\Users\User\AppData\Local\Programs\Python\Python312\Lib\site-packages\telebot\__init__.py", line 1234, in __threaded_polling
    polling_thread.raise_exceptions()
  File "c:\Users\User\AppData\Local\Programs\Python\Python312\Lib\site-packages\telebot\util.py", line 111, in raise_exceptions
    raise self.exception_info
  File "c:\Users\User\AppData\Local\Programs\Python\Python312\Lib\site-packages\telebot\util.py", line 93, in run
    task(*args, **kwargs)
  File "c:\Users\User\AppData\Local\Programs\Python\Python312\Lib\site-packages\telebot\__init__.py", line 688, in __retrieve_updates
    updates = self.get_updates(offset=(self.last_update_id + 1),
             ^^^^^^^^^^^^^^^^^^^^^^^^^^^^^^^^^^^^^^^^^^^^^^^^^^
  File "c:\Users\User\AppData\Local\Programs\Python\Python312\Lib\site-packages\telebot\__init__.py", line 660, in get_updates
    json_updates = apihelper.get_updates(
                   ^^^^^^^^^^^^^^^^^^^^^^
  File "c:\Users\User\AppData\Local\Programs\Python\Python312\Lib\site-packages\telebot\apihelper.py", line 332, in get_updates
    return _make_request(token, method_url, params=payload)
           ^^^^^^^^^^^^^^^^^^^^^^^^^^^^^^^^^^^^^^^^^^^^^^^^
  File "c:\Users\User\AppData\Local\Programs\Python\Python312\Lib\site-packages\telebot\apihelper.py", line 162, in _make_request
    result = _get_req_session().request(
             ^^^^^^^^^^^^^^^^^^^^^^^^^^^
  File "c:\Users\User\AppData\Local\Programs\Python\Python312\Lib\site-packages\requests\sessions.py", line 589, in request
    resp = self.send(prep, **send_kwargs)
           ^^^^^^^^^^^^^^^^^^^^^^^^^^^^^^
  File "c:\Users\User\AppData\Local\Programs\Python\Python312\Lib\site-packages\requests\sessions.py", line 703, in send
    r = adapter.send(request, **kwargs)
        ^^^^^^^^^^^^^^^^^^^^^^^^^^^^^^^
  File "c:\Users\User\AppData\Local\Programs\Python\Python312\Lib\site-packages\requests\adapters.py", line 700, in send
    raise ConnectionError(e, request=request)
requests.exceptions.ConnectionError: HTTPSConnectionPool(host='api.telegram.org', port=443): Max retries exceeded with url: /bot8120214959:***********************************/getUpdates?offset=1&timeout=20 (Caused by NameResolutionError("<urllib3.connection.HTTPSConnection object at 0x000001851BF9EB10>: Failed to resolve 'api.telegram.org' ([Errno 11001] getaddrinfo failed)"))

2025-07-23 21:03:38,875 - TeleBot - ERROR - Infinity polling exception: HTTPSConnectionPool(host='api.telegram.org', port=443): Max retries exceeded with url: /bot8120214959:***********************************/getUpdates?offset=1&timeout=20 (Caused by NameResolutionError("<urllib3.connection.HTTPSConnection object at 0x000001851C46A090>: Failed to resolve 'api.telegram.org' ([Errno 11001] getaddrinfo failed)"))
2025-07-23 21:03:38,903 - TeleBot - ERROR - Exception traceback:
Traceback (most recent call last):
  File "c:\Users\User\AppData\Local\Programs\Python\Python312\Lib\site-packages\urllib3\connection.py", line 198, in _new_conn
    sock = connection.create_connection(
           ^^^^^^^^^^^^^^^^^^^^^^^^^^^^^
  File "c:\Users\User\AppData\Local\Programs\Python\Python312\Lib\site-packages\urllib3\util\connection.py", line 60, in create_connection
    for res in socket.getaddrinfo(host, port, family, socket.SOCK_STREAM):
               ^^^^^^^^^^^^^^^^^^^^^^^^^^^^^^^^^^^^^^^^^^^^^^^^^^^^^^^^^^
  File "c:\Users\User\AppData\Local\Programs\Python\Python312\Lib\socket.py", line 976, in getaddrinfo
    for res in _socket.getaddrinfo(host, port, family, type, proto, flags):
               ^^^^^^^^^^^^^^^^^^^^^^^^^^^^^^^^^^^^^^^^^^^^^^^^^^^^^^^^^^^
socket.gaierror: [Errno 11001] getaddrinfo failed

The above exception was the direct cause of the following exception:

Traceback (most recent call last):
  File "c:\Users\User\AppData\Local\Programs\Python\Python312\Lib\site-packages\urllib3\connectionpool.py", line 787, in urlopen
    response = self._make_request(
               ^^^^^^^^^^^^^^^^^^^
  File "c:\Users\User\AppData\Local\Programs\Python\Python312\Lib\site-packages\urllib3\connectionpool.py", line 488, in _make_request
    raise new_e
  File "c:\Users\User\AppData\Local\Programs\Python\Python312\Lib\site-packages\urllib3\connectionpool.py", line 464, in _make_request
    self._validate_conn(conn)
  File "c:\Users\User\AppData\Local\Programs\Python\Python312\Lib\site-packages\urllib3\connectionpool.py", line 1093, in _validate_conn
    conn.connect()
  File "c:\Users\User\AppData\Local\Programs\Python\Python312\Lib\site-packages\urllib3\connection.py", line 753, in connect
    self.sock = sock = self._new_conn()
                       ^^^^^^^^^^^^^^^^
  File "c:\Users\User\AppData\Local\Programs\Python\Python312\Lib\site-packages\urllib3\connection.py", line 205, in _new_conn
    raise NameResolutionError(self.host, self, e) from e
urllib3.exceptions.NameResolutionError: <urllib3.connection.HTTPSConnection object at 0x000001851C46A090>: Failed to resolve 'api.telegram.org' ([Errno 11001] getaddrinfo failed)

The above exception was the direct cause of the following exception:

Traceback (most recent call last):
  File "c:\Users\User\AppData\Local\Programs\Python\Python312\Lib\site-packages\requests\adapters.py", line 667, in send
    resp = conn.urlopen(
           ^^^^^^^^^^^^^
  File "c:\Users\User\AppData\Local\Programs\Python\Python312\Lib\site-packages\urllib3\connectionpool.py", line 841, in urlopen
    retries = retries.increment(
              ^^^^^^^^^^^^^^^^^^
  File "c:\Users\User\AppData\Local\Programs\Python\Python312\Lib\site-packages\urllib3\util\retry.py", line 519, in increment
    raise MaxRetryError(_pool, url, reason) from reason  # type: ignore[arg-type]
    ^^^^^^^^^^^^^^^^^^^^^^^^^^^^^^^^^^^^^^^^^^^^^^^^^^^
urllib3.exceptions.MaxRetryError: HTTPSConnectionPool(host='api.telegram.org', port=443): Max retries exceeded with url: /bot8120214959:***********************************/getUpdates?offset=1&timeout=20 (Caused by NameResolutionError("<urllib3.connection.HTTPSConnection object at 0x000001851C46A090>: Failed to resolve 'api.telegram.org' ([Errno 11001] getaddrinfo failed)"))

During handling of the above exception, another exception occurred:

Traceback (most recent call last):
  File "c:\Users\User\AppData\Local\Programs\Python\Python312\Lib\site-packages\telebot\__init__.py", line 1110, in infinity_polling
    self.polling(non_stop=True, timeout=timeout, long_polling_timeout=long_polling_timeout,
  File "c:\Users\User\AppData\Local\Programs\Python\Python312\Lib\site-packages\telebot\__init__.py", line 1198, in polling
    self.__threaded_polling(non_stop=non_stop, interval=interval, timeout=timeout, long_polling_timeout=long_polling_timeout,
  File "c:\Users\User\AppData\Local\Programs\Python\Python312\Lib\site-packages\telebot\__init__.py", line 1273, in __threaded_polling
    raise e
  File "c:\Users\User\AppData\Local\Programs\Python\Python312\Lib\site-packages\telebot\__init__.py", line 1234, in __threaded_polling
    polling_thread.raise_exceptions()
  File "c:\Users\User\AppData\Local\Programs\Python\Python312\Lib\site-packages\telebot\util.py", line 111, in raise_exceptions
    raise self.exception_info
  File "c:\Users\User\AppData\Local\Programs\Python\Python312\Lib\site-packages\telebot\util.py", line 93, in run
    task(*args, **kwargs)
  File "c:\Users\User\AppData\Local\Programs\Python\Python312\Lib\site-packages\telebot\__init__.py", line 688, in __retrieve_updates
    updates = self.get_updates(offset=(self.last_update_id + 1),
             ^^^^^^^^^^^^^^^^^^^^^^^^^^^^^^^^^^^^^^^^^^^^^^^^^^
  File "c:\Users\User\AppData\Local\Programs\Python\Python312\Lib\site-packages\telebot\__init__.py", line 660, in get_updates
    json_updates = apihelper.get_updates(
                   ^^^^^^^^^^^^^^^^^^^^^^
  File "c:\Users\User\AppData\Local\Programs\Python\Python312\Lib\site-packages\telebot\apihelper.py", line 332, in get_updates
    return _make_request(token, method_url, params=payload)
           ^^^^^^^^^^^^^^^^^^^^^^^^^^^^^^^^^^^^^^^^^^^^^^^^
  File "c:\Users\User\AppData\Local\Programs\Python\Python312\Lib\site-packages\telebot\apihelper.py", line 162, in _make_request
    result = _get_req_session().request(
             ^^^^^^^^^^^^^^^^^^^^^^^^^^^
  File "c:\Users\User\AppData\Local\Programs\Python\Python312\Lib\site-packages\requests\sessions.py", line 589, in request
    resp = self.send(prep, **send_kwargs)
           ^^^^^^^^^^^^^^^^^^^^^^^^^^^^^^
  File "c:\Users\User\AppData\Local\Programs\Python\Python312\Lib\site-packages\requests\sessions.py", line 703, in send
    r = adapter.send(request, **kwargs)
        ^^^^^^^^^^^^^^^^^^^^^^^^^^^^^^^
  File "c:\Users\User\AppData\Local\Programs\Python\Python312\Lib\site-packages\requests\adapters.py", line 700, in send
    raise ConnectionError(e, request=request)
requests.exceptions.ConnectionError: HTTPSConnectionPool(host='api.telegram.org', port=443): Max retries exceeded with url: /bot8120214959:***********************************/getUpdates?offset=1&timeout=20 (Caused by NameResolutionError("<urllib3.connection.HTTPSConnection object at 0x000001851C46A090>: Failed to resolve 'api.telegram.org' ([Errno 11001] getaddrinfo failed)"))

2025-07-23 21:03:41,945 - TeleBot - ERROR - Infinity polling exception: HTTPSConnectionPool(host='api.telegram.org', port=443): Max retries exceeded with url: /bot8120214959:***********************************/getUpdates?offset=1&timeout=20 (Caused by NameResolutionError("<urllib3.connection.HTTPSConnection object at 0x000001851C46BAD0>: Failed to resolve 'api.telegram.org' ([Errno 11001] getaddrinfo failed)"))
2025-07-23 21:03:41,967 - TeleBot - ERROR - Exception traceback:
Traceback (most recent call last):
  File "c:\Users\User\AppData\Local\Programs\Python\Python312\Lib\site-packages\urllib3\connection.py", line 198, in _new_conn
    sock = connection.create_connection(
           ^^^^^^^^^^^^^^^^^^^^^^^^^^^^^
  File "c:\Users\User\AppData\Local\Programs\Python\Python312\Lib\site-packages\urllib3\util\connection.py", line 60, in create_connection
    for res in socket.getaddrinfo(host, port, family, socket.SOCK_STREAM):
               ^^^^^^^^^^^^^^^^^^^^^^^^^^^^^^^^^^^^^^^^^^^^^^^^^^^^^^^^^^
  File "c:\Users\User\AppData\Local\Programs\Python\Python312\Lib\socket.py", line 976, in getaddrinfo
    for res in _socket.getaddrinfo(host, port, family, type, proto, flags):
               ^^^^^^^^^^^^^^^^^^^^^^^^^^^^^^^^^^^^^^^^^^^^^^^^^^^^^^^^^^^
socket.gaierror: [Errno 11001] getaddrinfo failed

The above exception was the direct cause of the following exception:

Traceback (most recent call last):
  File "c:\Users\User\AppData\Local\Programs\Python\Python312\Lib\site-packages\urllib3\connectionpool.py", line 787, in urlopen
    response = self._make_request(
               ^^^^^^^^^^^^^^^^^^^
  File "c:\Users\User\AppData\Local\Programs\Python\Python312\Lib\site-packages\urllib3\connectionpool.py", line 488, in _make_request
    raise new_e
  File "c:\Users\User\AppData\Local\Programs\Python\Python312\Lib\site-packages\urllib3\connectionpool.py", line 464, in _make_request
    self._validate_conn(conn)
  File "c:\Users\User\AppData\Local\Programs\Python\Python312\Lib\site-packages\urllib3\connectionpool.py", line 1093, in _validate_conn
    conn.connect()
  File "c:\Users\User\AppData\Local\Programs\Python\Python312\Lib\site-packages\urllib3\connection.py", line 753, in connect
    self.sock = sock = self._new_conn()
                       ^^^^^^^^^^^^^^^^
  File "c:\Users\User\AppData\Local\Programs\Python\Python312\Lib\site-packages\urllib3\connection.py", line 205, in _new_conn
    raise NameResolutionError(self.host, self, e) from e
urllib3.exceptions.NameResolutionError: <urllib3.connection.HTTPSConnection object at 0x000001851C46BAD0>: Failed to resolve 'api.telegram.org' ([Errno 11001] getaddrinfo failed)

The above exception was the direct cause of the following exception:

Traceback (most recent call last):
  File "c:\Users\User\AppData\Local\Programs\Python\Python312\Lib\site-packages\requests\adapters.py", line 667, in send
    resp = conn.urlopen(
           ^^^^^^^^^^^^^
  File "c:\Users\User\AppData\Local\Programs\Python\Python312\Lib\site-packages\urllib3\connectionpool.py", line 841, in urlopen
    retries = retries.increment(
              ^^^^^^^^^^^^^^^^^^
  File "c:\Users\User\AppData\Local\Programs\Python\Python312\Lib\site-packages\urllib3\util\retry.py", line 519, in increment
    raise MaxRetryError(_pool, url, reason) from reason  # type: ignore[arg-type]
    ^^^^^^^^^^^^^^^^^^^^^^^^^^^^^^^^^^^^^^^^^^^^^^^^^^^
urllib3.exceptions.MaxRetryError: HTTPSConnectionPool(host='api.telegram.org', port=443): Max retries exceeded with url: /bot8120214959:***********************************/getUpdates?offset=1&timeout=20 (Caused by NameResolutionError("<urllib3.connection.HTTPSConnection object at 0x000001851C46BAD0>: Failed to resolve 'api.telegram.org' ([Errno 11001] getaddrinfo failed)"))

During handling of the above exception, another exception occurred:

Traceback (most recent call last):
  File "c:\Users\User\AppData\Local\Programs\Python\Python312\Lib\site-packages\telebot\__init__.py", line 1110, in infinity_polling
    self.polling(non_stop=True, timeout=timeout, long_polling_timeout=long_polling_timeout,
  File "c:\Users\User\AppData\Local\Programs\Python\Python312\Lib\site-packages\telebot\__init__.py", line 1198, in polling
    self.__threaded_polling(non_stop=non_stop, interval=interval, timeout=timeout, long_polling_timeout=long_polling_timeout,
  File "c:\Users\User\AppData\Local\Programs\Python\Python312\Lib\site-packages\telebot\__init__.py", line 1273, in __threaded_polling
    raise e
  File "c:\Users\User\AppData\Local\Programs\Python\Python312\Lib\site-packages\telebot\__init__.py", line 1234, in __threaded_polling
    polling_thread.raise_exceptions()
  File "c:\Users\User\AppData\Local\Programs\Python\Python312\Lib\site-packages\telebot\util.py", line 111, in raise_exceptions
    raise self.exception_info
  File "c:\Users\User\AppData\Local\Programs\Python\Python312\Lib\site-packages\telebot\util.py", line 93, in run
    task(*args, **kwargs)
  File "c:\Users\User\AppData\Local\Programs\Python\Python312\Lib\site-packages\telebot\__init__.py", line 688, in __retrieve_updates
    updates = self.get_updates(offset=(self.last_update_id + 1),
             ^^^^^^^^^^^^^^^^^^^^^^^^^^^^^^^^^^^^^^^^^^^^^^^^^^
  File "c:\Users\User\AppData\Local\Programs\Python\Python312\Lib\site-packages\telebot\__init__.py", line 660, in get_updates
    json_updates = apihelper.get_updates(
                   ^^^^^^^^^^^^^^^^^^^^^^
  File "c:\Users\User\AppData\Local\Programs\Python\Python312\Lib\site-packages\telebot\apihelper.py", line 332, in get_updates
    return _make_request(token, method_url, params=payload)
           ^^^^^^^^^^^^^^^^^^^^^^^^^^^^^^^^^^^^^^^^^^^^^^^^
  File "c:\Users\User\AppData\Local\Programs\Python\Python312\Lib\site-packages\telebot\apihelper.py", line 162, in _make_request
    result = _get_req_session().request(
             ^^^^^^^^^^^^^^^^^^^^^^^^^^^
  File "c:\Users\User\AppData\Local\Programs\Python\Python312\Lib\site-packages\requests\sessions.py", line 589, in request
    resp = self.send(prep, **send_kwargs)
           ^^^^^^^^^^^^^^^^^^^^^^^^^^^^^^
  File "c:\Users\User\AppData\Local\Programs\Python\Python312\Lib\site-packages\requests\sessions.py", line 703, in send
    r = adapter.send(request, **kwargs)
        ^^^^^^^^^^^^^^^^^^^^^^^^^^^^^^^
  File "c:\Users\User\AppData\Local\Programs\Python\Python312\Lib\site-packages\requests\adapters.py", line 700, in send
    raise ConnectionError(e, request=request)
requests.exceptions.ConnectionError: HTTPSConnectionPool(host='api.telegram.org', port=443): Max retries exceeded with url: /bot8120214959:***********************************/getUpdates?offset=1&timeout=20 (Caused by NameResolutionError("<urllib3.connection.HTTPSConnection object at 0x000001851C46BAD0>: Failed to resolve 'api.telegram.org' ([Errno 11001] getaddrinfo failed)"))

2025-07-23 21:03:45,011 - TeleBot - ERROR - Infinity polling exception: HTTPSConnectionPool(host='api.telegram.org', port=443): Max retries exceeded with url: /bot8120214959:***********************************/getUpdates?offset=1&timeout=20 (Caused by NameResolutionError("<urllib3.connection.HTTPSConnection object at 0x000001851BF9F590>: Failed to resolve 'api.telegram.org' ([Errno 11001] getaddrinfo failed)"))
2025-07-23 21:03:45,021 - TeleBot - ERROR - Exception traceback:
Traceback (most recent call last):
  File "c:\Users\User\AppData\Local\Programs\Python\Python312\Lib\site-packages\urllib3\connection.py", line 198, in _new_conn
    sock = connection.create_connection(
           ^^^^^^^^^^^^^^^^^^^^^^^^^^^^^
  File "c:\Users\User\AppData\Local\Programs\Python\Python312\Lib\site-packages\urllib3\util\connection.py", line 60, in create_connection
    for res in socket.getaddrinfo(host, port, family, socket.SOCK_STREAM):
               ^^^^^^^^^^^^^^^^^^^^^^^^^^^^^^^^^^^^^^^^^^^^^^^^^^^^^^^^^^
  File "c:\Users\User\AppData\Local\Programs\Python\Python312\Lib\socket.py", line 976, in getaddrinfo
    for res in _socket.getaddrinfo(host, port, family, type, proto, flags):
               ^^^^^^^^^^^^^^^^^^^^^^^^^^^^^^^^^^^^^^^^^^^^^^^^^^^^^^^^^^^
socket.gaierror: [Errno 11001] getaddrinfo failed

The above exception was the direct cause of the following exception:

Traceback (most recent call last):
  File "c:\Users\User\AppData\Local\Programs\Python\Python312\Lib\site-packages\urllib3\connectionpool.py", line 787, in urlopen
    response = self._make_request(
               ^^^^^^^^^^^^^^^^^^^
  File "c:\Users\User\AppData\Local\Programs\Python\Python312\Lib\site-packages\urllib3\connectionpool.py", line 488, in _make_request
    raise new_e
  File "c:\Users\User\AppData\Local\Programs\Python\Python312\Lib\site-packages\urllib3\connectionpool.py", line 464, in _make_request
    self._validate_conn(conn)
  File "c:\Users\User\AppData\Local\Programs\Python\Python312\Lib\site-packages\urllib3\connectionpool.py", line 1093, in _validate_conn
    conn.connect()
  File "c:\Users\User\AppData\Local\Programs\Python\Python312\Lib\site-packages\urllib3\connection.py", line 753, in connect
    self.sock = sock = self._new_conn()
                       ^^^^^^^^^^^^^^^^
  File "c:\Users\User\AppData\Local\Programs\Python\Python312\Lib\site-packages\urllib3\connection.py", line 205, in _new_conn
    raise NameResolutionError(self.host, self, e) from e
urllib3.exceptions.NameResolutionError: <urllib3.connection.HTTPSConnection object at 0x000001851BF9F590>: Failed to resolve 'api.telegram.org' ([Errno 11001] getaddrinfo failed)

The above exception was the direct cause of the following exception:

Traceback (most recent call last):
  File "c:\Users\User\AppData\Local\Programs\Python\Python312\Lib\site-packages\requests\adapters.py", line 667, in send
    resp = conn.urlopen(
           ^^^^^^^^^^^^^
  File "c:\Users\User\AppData\Local\Programs\Python\Python312\Lib\site-packages\urllib3\connectionpool.py", line 841, in urlopen
    retries = retries.increment(
              ^^^^^^^^^^^^^^^^^^
  File "c:\Users\User\AppData\Local\Programs\Python\Python312\Lib\site-packages\urllib3\util\retry.py", line 519, in increment
    raise MaxRetryError(_pool, url, reason) from reason  # type: ignore[arg-type]
    ^^^^^^^^^^^^^^^^^^^^^^^^^^^^^^^^^^^^^^^^^^^^^^^^^^^
urllib3.exceptions.MaxRetryError: HTTPSConnectionPool(host='api.telegram.org', port=443): Max retries exceeded with url: /bot8120214959:***********************************/getUpdates?offset=1&timeout=20 (Caused by NameResolutionError("<urllib3.connection.HTTPSConnection object at 0x000001851BF9F590>: Failed to resolve 'api.telegram.org' ([Errno 11001] getaddrinfo failed)"))

During handling of the above exception, another exception occurred:

Traceback (most recent call last):
  File "c:\Users\User\AppData\Local\Programs\Python\Python312\Lib\site-packages\telebot\__init__.py", line 1110, in infinity_polling
    self.polling(non_stop=True, timeout=timeout, long_polling_timeout=long_polling_timeout,
  File "c:\Users\User\AppData\Local\Programs\Python\Python312\Lib\site-packages\telebot\__init__.py", line 1198, in polling
    self.__threaded_polling(non_stop=non_stop, interval=interval, timeout=timeout, long_polling_timeout=long_polling_timeout,
  File "c:\Users\User\AppData\Local\Programs\Python\Python312\Lib\site-packages\telebot\__init__.py", line 1273, in __threaded_polling
    raise e
  File "c:\Users\User\AppData\Local\Programs\Python\Python312\Lib\site-packages\telebot\__init__.py", line 1234, in __threaded_polling
    polling_thread.raise_exceptions()
  File "c:\Users\User\AppData\Local\Programs\Python\Python312\Lib\site-packages\telebot\util.py", line 111, in raise_exceptions
    raise self.exception_info
  File "c:\Users\User\AppData\Local\Programs\Python\Python312\Lib\site-packages\telebot\util.py", line 93, in run
    task(*args, **kwargs)
  File "c:\Users\User\AppData\Local\Programs\Python\Python312\Lib\site-packages\telebot\__init__.py", line 688, in __retrieve_updates
    updates = self.get_updates(offset=(self.last_update_id + 1),
             ^^^^^^^^^^^^^^^^^^^^^^^^^^^^^^^^^^^^^^^^^^^^^^^^^^
  File "c:\Users\User\AppData\Local\Programs\Python\Python312\Lib\site-packages\telebot\__init__.py", line 660, in get_updates
    json_updates = apihelper.get_updates(
                   ^^^^^^^^^^^^^^^^^^^^^^
  File "c:\Users\User\AppData\Local\Programs\Python\Python312\Lib\site-packages\telebot\apihelper.py", line 332, in get_updates
    return _make_request(token, method_url, params=payload)
           ^^^^^^^^^^^^^^^^^^^^^^^^^^^^^^^^^^^^^^^^^^^^^^^^
  File "c:\Users\User\AppData\Local\Programs\Python\Python312\Lib\site-packages\telebot\apihelper.py", line 162, in _make_request
    result = _get_req_session().request(
             ^^^^^^^^^^^^^^^^^^^^^^^^^^^
  File "c:\Users\User\AppData\Local\Programs\Python\Python312\Lib\site-packages\requests\sessions.py", line 589, in request
    resp = self.send(prep, **send_kwargs)
           ^^^^^^^^^^^^^^^^^^^^^^^^^^^^^^
  File "c:\Users\User\AppData\Local\Programs\Python\Python312\Lib\site-packages\requests\sessions.py", line 703, in send
    r = adapter.send(request, **kwargs)
        ^^^^^^^^^^^^^^^^^^^^^^^^^^^^^^^
  File "c:\Users\User\AppData\Local\Programs\Python\Python312\Lib\site-packages\requests\adapters.py", line 700, in send
    raise ConnectionError(e, request=request)
requests.exceptions.ConnectionError: HTTPSConnectionPool(host='api.telegram.org', port=443): Max retries exceeded with url: /bot8120214959:***********************************/getUpdates?offset=1&timeout=20 (Caused by NameResolutionError("<urllib3.connection.HTTPSConnection object at 0x000001851BF9F590>: Failed to resolve 'api.telegram.org' ([Errno 11001] getaddrinfo failed)"))

2025-07-23 21:03:48,035 - TeleBot - ERROR - Infinity polling exception: HTTPSConnectionPool(host='api.telegram.org', port=443): Max retries exceeded with url: /bot8120214959:***********************************/getUpdates?offset=1&timeout=20 (Caused by NameResolutionError("<urllib3.connection.HTTPSConnection object at 0x000001851C46BE60>: Failed to resolve 'api.telegram.org' ([Errno 11001] getaddrinfo failed)"))
2025-07-23 21:03:48,041 - TeleBot - ERROR - Exception traceback:
Traceback (most recent call last):
  File "c:\Users\User\AppData\Local\Programs\Python\Python312\Lib\site-packages\urllib3\connection.py", line 198, in _new_conn
    sock = connection.create_connection(
           ^^^^^^^^^^^^^^^^^^^^^^^^^^^^^
  File "c:\Users\User\AppData\Local\Programs\Python\Python312\Lib\site-packages\urllib3\util\connection.py", line 60, in create_connection
    for res in socket.getaddrinfo(host, port, family, socket.SOCK_STREAM):
               ^^^^^^^^^^^^^^^^^^^^^^^^^^^^^^^^^^^^^^^^^^^^^^^^^^^^^^^^^^
  File "c:\Users\User\AppData\Local\Programs\Python\Python312\Lib\socket.py", line 976, in getaddrinfo
    for res in _socket.getaddrinfo(host, port, family, type, proto, flags):
               ^^^^^^^^^^^^^^^^^^^^^^^^^^^^^^^^^^^^^^^^^^^^^^^^^^^^^^^^^^^
socket.gaierror: [Errno 11001] getaddrinfo failed

The above exception was the direct cause of the following exception:

Traceback (most recent call last):
  File "c:\Users\User\AppData\Local\Programs\Python\Python312\Lib\site-packages\urllib3\connectionpool.py", line 787, in urlopen
    response = self._make_request(
               ^^^^^^^^^^^^^^^^^^^
  File "c:\Users\User\AppData\Local\Programs\Python\Python312\Lib\site-packages\urllib3\connectionpool.py", line 488, in _make_request
    raise new_e
  File "c:\Users\User\AppData\Local\Programs\Python\Python312\Lib\site-packages\urllib3\connectionpool.py", line 464, in _make_request
    self._validate_conn(conn)
  File "c:\Users\User\AppData\Local\Programs\Python\Python312\Lib\site-packages\urllib3\connectionpool.py", line 1093, in _validate_conn
    conn.connect()
  File "c:\Users\User\AppData\Local\Programs\Python\Python312\Lib\site-packages\urllib3\connection.py", line 753, in connect
    self.sock = sock = self._new_conn()
                       ^^^^^^^^^^^^^^^^
  File "c:\Users\User\AppData\Local\Programs\Python\Python312\Lib\site-packages\urllib3\connection.py", line 205, in _new_conn
    raise NameResolutionError(self.host, self, e) from e
urllib3.exceptions.NameResolutionError: <urllib3.connection.HTTPSConnection object at 0x000001851C46BE60>: Failed to resolve 'api.telegram.org' ([Errno 11001] getaddrinfo failed)

The above exception was the direct cause of the following exception:

Traceback (most recent call last):
  File "c:\Users\User\AppData\Local\Programs\Python\Python312\Lib\site-packages\requests\adapters.py", line 667, in send
    resp = conn.urlopen(
           ^^^^^^^^^^^^^
  File "c:\Users\User\AppData\Local\Programs\Python\Python312\Lib\site-packages\urllib3\connectionpool.py", line 841, in urlopen
    retries = retries.increment(
              ^^^^^^^^^^^^^^^^^^
  File "c:\Users\User\AppData\Local\Programs\Python\Python312\Lib\site-packages\urllib3\util\retry.py", line 519, in increment
    raise MaxRetryError(_pool, url, reason) from reason  # type: ignore[arg-type]
    ^^^^^^^^^^^^^^^^^^^^^^^^^^^^^^^^^^^^^^^^^^^^^^^^^^^
urllib3.exceptions.MaxRetryError: HTTPSConnectionPool(host='api.telegram.org', port=443): Max retries exceeded with url: /bot8120214959:***********************************/getUpdates?offset=1&timeout=20 (Caused by NameResolutionError("<urllib3.connection.HTTPSConnection object at 0x000001851C46BE60>: Failed to resolve 'api.telegram.org' ([Errno 11001] getaddrinfo failed)"))

During handling of the above exception, another exception occurred:

Traceback (most recent call last):
  File "c:\Users\User\AppData\Local\Programs\Python\Python312\Lib\site-packages\telebot\__init__.py", line 1110, in infinity_polling
    self.polling(non_stop=True, timeout=timeout, long_polling_timeout=long_polling_timeout,
  File "c:\Users\User\AppData\Local\Programs\Python\Python312\Lib\site-packages\telebot\__init__.py", line 1198, in polling
    self.__threaded_polling(non_stop=non_stop, interval=interval, timeout=timeout, long_polling_timeout=long_polling_timeout,
  File "c:\Users\User\AppData\Local\Programs\Python\Python312\Lib\site-packages\telebot\__init__.py", line 1273, in __threaded_polling
    raise e
  File "c:\Users\User\AppData\Local\Programs\Python\Python312\Lib\site-packages\telebot\__init__.py", line 1234, in __threaded_polling
    polling_thread.raise_exceptions()
  File "c:\Users\User\AppData\Local\Programs\Python\Python312\Lib\site-packages\telebot\util.py", line 111, in raise_exceptions
    raise self.exception_info
  File "c:\Users\User\AppData\Local\Programs\Python\Python312\Lib\site-packages\telebot\util.py", line 93, in run
    task(*args, **kwargs)
  File "c:\Users\User\AppData\Local\Programs\Python\Python312\Lib\site-packages\telebot\__init__.py", line 688, in __retrieve_updates
    updates = self.get_updates(offset=(self.last_update_id + 1),
             ^^^^^^^^^^^^^^^^^^^^^^^^^^^^^^^^^^^^^^^^^^^^^^^^^^
  File "c:\Users\User\AppData\Local\Programs\Python\Python312\Lib\site-packages\telebot\__init__.py", line 660, in get_updates
    json_updates = apihelper.get_updates(
                   ^^^^^^^^^^^^^^^^^^^^^^
  File "c:\Users\User\AppData\Local\Programs\Python\Python312\Lib\site-packages\telebot\apihelper.py", line 332, in get_updates
    return _make_request(token, method_url, params=payload)
           ^^^^^^^^^^^^^^^^^^^^^^^^^^^^^^^^^^^^^^^^^^^^^^^^
  File "c:\Users\User\AppData\Local\Programs\Python\Python312\Lib\site-packages\telebot\apihelper.py", line 162, in _make_request
    result = _get_req_session().request(
             ^^^^^^^^^^^^^^^^^^^^^^^^^^^
  File "c:\Users\User\AppData\Local\Programs\Python\Python312\Lib\site-packages\requests\sessions.py", line 589, in request
    resp = self.send(prep, **send_kwargs)
           ^^^^^^^^^^^^^^^^^^^^^^^^^^^^^^
  File "c:\Users\User\AppData\Local\Programs\Python\Python312\Lib\site-packages\requests\sessions.py", line 703, in send
    r = adapter.send(request, **kwargs)
        ^^^^^^^^^^^^^^^^^^^^^^^^^^^^^^^
  File "c:\Users\User\AppData\Local\Programs\Python\Python312\Lib\site-packages\requests\adapters.py", line 700, in send
    raise ConnectionError(e, request=request)
requests.exceptions.ConnectionError: HTTPSConnectionPool(host='api.telegram.org', port=443): Max retries exceeded with url: /bot8120214959:***********************************/getUpdates?offset=1&timeout=20 (Caused by NameResolutionError("<urllib3.connection.HTTPSConnection object at 0x000001851C46BE60>: Failed to resolve 'api.telegram.org' ([Errno 11001] getaddrinfo failed)"))

2025-07-23 21:03:51,112 - TeleBot - ERROR - Infinity polling exception: HTTPSConnectionPool(host='api.telegram.org', port=443): Max retries exceeded with url: /bot8120214959:***********************************/getUpdates?offset=1&timeout=20 (Caused by NameResolutionError("<urllib3.connection.HTTPSConnection object at 0x000001851C490C80>: Failed to resolve 'api.telegram.org' ([Errno 11001] getaddrinfo failed)"))
2025-07-23 21:03:51,134 - TeleBot - ERROR - Exception traceback:
Traceback (most recent call last):
  File "c:\Users\User\AppData\Local\Programs\Python\Python312\Lib\site-packages\urllib3\connection.py", line 198, in _new_conn
    sock = connection.create_connection(
           ^^^^^^^^^^^^^^^^^^^^^^^^^^^^^
  File "c:\Users\User\AppData\Local\Programs\Python\Python312\Lib\site-packages\urllib3\util\connection.py", line 60, in create_connection
    for res in socket.getaddrinfo(host, port, family, socket.SOCK_STREAM):
               ^^^^^^^^^^^^^^^^^^^^^^^^^^^^^^^^^^^^^^^^^^^^^^^^^^^^^^^^^^
  File "c:\Users\User\AppData\Local\Programs\Python\Python312\Lib\socket.py", line 976, in getaddrinfo
    for res in _socket.getaddrinfo(host, port, family, type, proto, flags):
               ^^^^^^^^^^^^^^^^^^^^^^^^^^^^^^^^^^^^^^^^^^^^^^^^^^^^^^^^^^^
socket.gaierror: [Errno 11001] getaddrinfo failed

The above exception was the direct cause of the following exception:

Traceback (most recent call last):
  File "c:\Users\User\AppData\Local\Programs\Python\Python312\Lib\site-packages\urllib3\connectionpool.py", line 787, in urlopen
    response = self._make_request(
               ^^^^^^^^^^^^^^^^^^^
  File "c:\Users\User\AppData\Local\Programs\Python\Python312\Lib\site-packages\urllib3\connectionpool.py", line 488, in _make_request
    raise new_e
  File "c:\Users\User\AppData\Local\Programs\Python\Python312\Lib\site-packages\urllib3\connectionpool.py", line 464, in _make_request
    self._validate_conn(conn)
  File "c:\Users\User\AppData\Local\Programs\Python\Python312\Lib\site-packages\urllib3\connectionpool.py", line 1093, in _validate_conn
    conn.connect()
  File "c:\Users\User\AppData\Local\Programs\Python\Python312\Lib\site-packages\urllib3\connection.py", line 753, in connect
    self.sock = sock = self._new_conn()
                       ^^^^^^^^^^^^^^^^
  File "c:\Users\User\AppData\Local\Programs\Python\Python312\Lib\site-packages\urllib3\connection.py", line 205, in _new_conn
    raise NameResolutionError(self.host, self, e) from e
urllib3.exceptions.NameResolutionError: <urllib3.connection.HTTPSConnection object at 0x000001851C490C80>: Failed to resolve 'api.telegram.org' ([Errno 11001] getaddrinfo failed)

The above exception was the direct cause of the following exception:

Traceback (most recent call last):
  File "c:\Users\User\AppData\Local\Programs\Python\Python312\Lib\site-packages\requests\adapters.py", line 667, in send
    resp = conn.urlopen(
           ^^^^^^^^^^^^^
  File "c:\Users\User\AppData\Local\Programs\Python\Python312\Lib\site-packages\urllib3\connectionpool.py", line 841, in urlopen
    retries = retries.increment(
              ^^^^^^^^^^^^^^^^^^
  File "c:\Users\User\AppData\Local\Programs\Python\Python312\Lib\site-packages\urllib3\util\retry.py", line 519, in increment
    raise MaxRetryError(_pool, url, reason) from reason  # type: ignore[arg-type]
    ^^^^^^^^^^^^^^^^^^^^^^^^^^^^^^^^^^^^^^^^^^^^^^^^^^^
urllib3.exceptions.MaxRetryError: HTTPSConnectionPool(host='api.telegram.org', port=443): Max retries exceeded with url: /bot8120214959:***********************************/getUpdates?offset=1&timeout=20 (Caused by NameResolutionError("<urllib3.connection.HTTPSConnection object at 0x000001851C490C80>: Failed to resolve 'api.telegram.org' ([Errno 11001] getaddrinfo failed)"))

During handling of the above exception, another exception occurred:

Traceback (most recent call last):
  File "c:\Users\User\AppData\Local\Programs\Python\Python312\Lib\site-packages\telebot\__init__.py", line 1110, in infinity_polling
    self.polling(non_stop=True, timeout=timeout, long_polling_timeout=long_polling_timeout,
  File "c:\Users\User\AppData\Local\Programs\Python\Python312\Lib\site-packages\telebot\__init__.py", line 1198, in polling
    self.__threaded_polling(non_stop=non_stop, interval=interval, timeout=timeout, long_polling_timeout=long_polling_timeout,
  File "c:\Users\User\AppData\Local\Programs\Python\Python312\Lib\site-packages\telebot\__init__.py", line 1273, in __threaded_polling
    raise e
  File "c:\Users\User\AppData\Local\Programs\Python\Python312\Lib\site-packages\telebot\__init__.py", line 1234, in __threaded_polling
    polling_thread.raise_exceptions()
  File "c:\Users\User\AppData\Local\Programs\Python\Python312\Lib\site-packages\telebot\util.py", line 111, in raise_exceptions
    raise self.exception_info
  File "c:\Users\User\AppData\Local\Programs\Python\Python312\Lib\site-packages\telebot\util.py", line 93, in run
    task(*args, **kwargs)
  File "c:\Users\User\AppData\Local\Programs\Python\Python312\Lib\site-packages\telebot\__init__.py", line 688, in __retrieve_updates
    updates = self.get_updates(offset=(self.last_update_id + 1),
             ^^^^^^^^^^^^^^^^^^^^^^^^^^^^^^^^^^^^^^^^^^^^^^^^^^
  File "c:\Users\User\AppData\Local\Programs\Python\Python312\Lib\site-packages\telebot\__init__.py", line 660, in get_updates
    json_updates = apihelper.get_updates(
                   ^^^^^^^^^^^^^^^^^^^^^^
  File "c:\Users\User\AppData\Local\Programs\Python\Python312\Lib\site-packages\telebot\apihelper.py", line 332, in get_updates
    return _make_request(token, method_url, params=payload)
           ^^^^^^^^^^^^^^^^^^^^^^^^^^^^^^^^^^^^^^^^^^^^^^^^
  File "c:\Users\User\AppData\Local\Programs\Python\Python312\Lib\site-packages\telebot\apihelper.py", line 162, in _make_request
    result = _get_req_session().request(
             ^^^^^^^^^^^^^^^^^^^^^^^^^^^
  File "c:\Users\User\AppData\Local\Programs\Python\Python312\Lib\site-packages\requests\sessions.py", line 589, in request
    resp = self.send(prep, **send_kwargs)
           ^^^^^^^^^^^^^^^^^^^^^^^^^^^^^^
  File "c:\Users\User\AppData\Local\Programs\Python\Python312\Lib\site-packages\requests\sessions.py", line 703, in send
    r = adapter.send(request, **kwargs)
        ^^^^^^^^^^^^^^^^^^^^^^^^^^^^^^^
  File "c:\Users\User\AppData\Local\Programs\Python\Python312\Lib\site-packages\requests\adapters.py", line 700, in send
    raise ConnectionError(e, request=request)
requests.exceptions.ConnectionError: HTTPSConnectionPool(host='api.telegram.org', port=443): Max retries exceeded with url: /bot8120214959:***********************************/getUpdates?offset=1&timeout=20 (Caused by NameResolutionError("<urllib3.connection.HTTPSConnection object at 0x000001851C490C80>: Failed to resolve 'api.telegram.org' ([Errno 11001] getaddrinfo failed)"))

